Workbook

Sheet Timing浏览
A2: 动力总成支架开发 项目排期 | C2: 说明与设置：点左侧 + / − 展开或收起
A3: 时间刻度 | B3: 周 | C3: 起点策略 | D3: 项目开始 | E3: 偏移格数 | F3: 0 | DC3: =IF(SUM(排期计算!$AA$10:$AA$109)=0,$B$4,MIN(排期计算!$Y$10:$Y$109)) -> 46321 | DD3: =IF(SUM(排期计算!$AA$10:$AA$109)=0,$DC$3,MAX(排期计算!$Z$10:$Z$109)) -> 46345 | DE3: =IF($B$3="全项目",$DC$3,IF($D$3="今天",$B$4,IF($D$3="手动",$B$5,$DC$3))) -> 46321 | DF3: =IF($B$3="日",1,IF($B$3="周",7,IF($B$3="全项目",MAX(1,ROUNDUP(($DD$3-$DC$3+1)/24,0)),1))) -> 7 | DG3: =IF($B$3="月",EDATE(DATE(YEAR($DE$3),MONTH($DE$3),1),$F$3),IF($B$3="周",$DE$3-WEEKDAY($DE$3,2)+1,$DE$3)+$F$3*$DF$3) -> 46321 | DH3: =SUM(排期计算!$T$10:$T$109) -> 7
A4: 状态日期 | B4: 46321 | C4: 当前窗口 | D4: =TEXT(K9,"yyyy-mm-dd")&" 至 "&TEXT(DB6,"yyyy-mm-dd") -> 2026-10-26 至 2028-08-27
A5: 手动起点 | B5: 46321 | C5: 显示层级 | D5: 全部
A6: 红：逾期未完成 绿：已完成 紫：普通任务 深色：汇总 ◆：里程碑 | K6: =IF($B$3="月",EDATE(K9,1)-1,K9+$DF$3-1) -> 46327 | L6: =IF($B$3="月",EDATE(L9,1)-1,L9+$DF$3-1) -> 46334 | M6: =IF($B$3="月",EDATE(M9,1)-1,M9+$DF$3-1) -> 46341 | N6: =IF($B$3="月",EDATE(N9,1)-1,N9+$DF$3-1) -> 46348 | O6: =IF($B$3="月",EDATE(O9,1)-1,O9+$DF$3-1) -> 46355 | P6: =IF($B$3="月",EDATE(P9,1)-1,P9+$DF$3-1) -> 46362 | Q6: =IF($B$3="月",EDATE(Q9,1)-1,Q9+$DF$3-1) -> 46369 | R6: =IF($B$3="月",EDATE(R9,1)-1,R9+$DF$3-1) -> 46376 | ... DB6: =IF($B$3="月",EDATE(DB9,1)-1,DB9+$DF$3-1) -> 46992
A7: WBS | B7: 任务名称 | C7: 计划开始 | D7: 计划完成 | E7: 工期 | F7: 完成度 | G7: 状态 | H7: 负责人 | I7: 前置任务 | J7: 任务类型 | K7: =YEAR(K9)&"年" -> 2026年 | L7: =IF(YEAR(L9)<>YEAR(K9),YEAR(L9)&"年","") | M7: =IF(YEAR(M9)<>YEAR(L9),YEAR(M9)&"年","") | N7: =IF(YEAR(N9)<>YEAR(M9),YEAR(N9)&"年","") | O7: =IF(YEAR(O9)<>YEAR(N9),YEAR(O9)&"年","") | P7: =IF(YEAR(P9)<>YEAR(O9),YEAR(P9)&"年","") | Q7: =IF(YEAR(Q9)<>YEAR(P9),YEAR(Q9)&"年","") | R7: =IF(YEAR(R9)<>YEAR(Q9),YEAR(R9)&"年","") | S7: =IF(YEAR(S9)<>YEAR(R9),YEAR(S9)&"年","") | ... DB7: =IF(YEAR(DB9)<>YEAR(DA9),YEAR(DB9)&"年","")
K8: =MONTH(K9)&"月" -> 10月 | L8: =IF(OR(MONTH(L9)<>MONTH(K9),YEAR(L9)<>YEAR(K9)),MONTH(L9)&"月","") -> 11月 | M8: =IF(OR(MONTH(M9)<>MONTH(L9),YEAR(M9)<>YEAR(L9)),MONTH(M9)&"月","") | N8: =IF(OR(MONTH(N9)<>MONTH(M9),YEAR(N9)<>YEAR(M9)),MONTH(N9)&"月","") | O8: =IF(OR(MONTH(O9)<>MONTH(N9),YEAR(O9)<>YEAR(N9)),MONTH(O9)&"月","") | P8: =IF(OR(MONTH(P9)<>MONTH(O9),YEAR(P9)<>YEAR(O9)),MONTH(P9)&"月","") | Q8: =IF(OR(MONTH(Q9)<>MONTH(P9),YEAR(Q9)<>YEAR(P9)),MONTH(Q9)&"月","") -> 12月 | R8: =IF(OR(MONTH(R9)<>MONTH(Q9),YEAR(R9)<>YEAR(Q9)),MONTH(R9)&"月","") | S8: =IF(OR(MONTH(S9)<>MONTH(R9),YEAR(S9)<>YEAR(R9)),MONTH(S9)&"月","") | ... DB8: =IF(OR(MONTH(DB9)<>MONTH(DA9),YEAR(DB9)<>YEAR(DA9)),MONTH(DB9)&"月","")
K9: =IF($B$3="月",EDATE($DG$3,0),$DG$3+0*$DF$3) -> 46321 | L9: =IF($B$3="月",EDATE($DG$3,1),$DG$3+1*$DF$3) -> 46328 | M9: =IF($B$3="月",EDATE($DG$3,2),$DG$3+2*$DF$3) -> 46335 | N9: =IF($B$3="月",EDATE($DG$3,3),$DG$3+3*$DF$3) -> 46342 | O9: =IF($B$3="月",EDATE($DG$3,4),$DG$3+4*$DF$3) -> 46349 | P9: =IF($B$3="月",EDATE($DG$3,5),$DG$3+5*$DF$3) -> 46356 | Q9: =IF($B$3="月",EDATE($DG$3,6),$DG$3+6*$DF$3) -> 46363 | R9: =IF($B$3="月",EDATE($DG$3,7),$DG$3+7*$DF$3) -> 46370 | S9: =IF($B$3="月",EDATE($DG$3,8),$DG$3+8*$DF$3) -> 46377 | T9: =IF($B$3="月",EDATE($DG$3,9),$DG$3+9*$DF$3) -> 46384 | U9: =IF($B$3="月",EDATE($DG$3,10),$DG$3+10*$DF$3) -> 46391 | V9: =IF($B$3="月",EDATE($DG$3,11),$DG$3+11*$DF$3) -> 46398 | W9: =IF($B$3="月",EDATE($DG$3,12),$DG$3+12*$DF$3) -> 46405 | X9: =IF($B$3="月",EDATE($DG$3,13),$DG$3+13*$DF$3) -> 46412 | Y9: =IF($B$3="月",EDATE($DG$3,14),$DG$3+14*$DF$3) -> 46419 | Z9: =IF($B$3="月",EDATE($DG$3,15),$DG$3+15*$DF$3) -> 46426 | AA9: =IF($B$3="月",EDATE($DG$3,16),$DG$3+16*$DF$3) -> 46433 | AB9: =IF($B$3="月",EDATE($DG$3,17),$DG$3+17*$DF$3) -> 46440 | AC9: =IF($B$3="月",EDATE($DG$3,18),$DG$3+18*$DF$3) -> 46447 | AD9: =IF($B$3="月",EDATE($DG$3,19),$DG$3+19*$DF$3) -> 46454 | AE9: =IF($B$3="月",EDATE($DG$3,20),$DG$3+20*$DF$3) -> 46461 | AF9: =IF($B$3="月",EDATE($DG$3,21),$DG$3+21*$DF$3) -> 46468 | AG9: =IF($B$3="月",EDATE($DG$3,22),$DG$3+22*$DF$3) -> 46475 | AH9: =IF($B$3="月",EDATE($DG$3,23),$DG$3+23*$DF$3) -> 46482 | AI9: =IF($B$3="月",EDATE($DG$3,24),$DG$3+24*$DF$3) -> 46489 | AJ9: =IF($B$3="月",EDATE($DG$3,25),$DG$3+25*$DF$3) -> 46496 | AK9: =IF($B$3="月",EDATE($DG$3,26),$DG$3+26*$DF$3) -> 46503 | AL9: =IF($B$3="月",EDATE($DG$3,27),$DG$3+27*$DF$3) -> 46510 | AM9: =IF($B$3="月",EDATE($DG$3,28),$DG$3+28*$DF$3) -> 46517 | AN9: =IF($B$3="月",EDATE($DG$3,29),$DG$3+29*$DF$3) -> 46524 | AO9: =IF($B$3="月",EDATE($DG$3,30),$DG$3+30*$DF$3) -> 46531 | AP9: =IF($B$3="月",EDATE($DG$3,31),$DG$3+31*$DF$3) -> 46538 | AQ9: =IF($B$3="月",EDATE($DG$3,32),$DG$3+32*$DF$3) -> 46545 | AR9: =IF($B$3="月",EDATE($DG$3,33),$DG$3+33*$DF$3) -> 46552 | AS9: =IF($B$3="月",EDATE($DG$3,34),$DG$3+34*$DF$3) -> 46559 | AT9: =IF($B$3="月",EDATE($DG$3,35),$DG$3+35*$DF$3) -> 46566 | AU9: =IF($B$3="月",EDATE($DG$3,36),$DG$3+36*$DF$3) -> 46573 | AV9: =IF($B$3="月",EDATE($DG$3,37),$DG$3+37*$DF$3) -> 46580 | AW9: =IF($B$3="月",EDATE($DG$3,38),$DG$3+38*$DF$3) -> 46587 | AX9: =IF($B$3="月",EDATE($DG$3,39),$DG$3+39*$DF$3) -> 46594 | AY9: =IF($B$3="月",EDATE($DG$3,40),$DG$3+40*$DF$3) -> 46601 | AZ9: =IF($B$3="月",EDATE($DG$3,41),$DG$3+41*$DF$3) -> 46608 | BA9: =IF($B$3="月",EDATE($DG$3,42),$DG$3+42*$DF$3) -> 46615 | BB9: =IF($B$3="月",EDATE($DG$3,43),$DG$3+43*$DF$3) -> 46622 | BC9: =IF($B$3="月",EDATE($DG$3,44),$DG$3+44*$DF$3) -> 46629 | BD9: =IF($B$3="月",EDATE($DG$3,45),$DG$3+45*$DF$3) -> 46636 | BE9: =IF($B$3="月",EDATE($DG$3,46),$DG$3+46*$DF$3) -> 46643 | BF9: =IF($B$3="月",EDATE($DG$3,47),$DG$3+47*$DF$3) -> 46650 | BG9: =IF($B$3="月",EDATE($DG$3,48),$DG$3+48*$DF$3) -> 46657 | BH9: =IF($B$3="月",EDATE($DG$3,49),$DG$3+49*$DF$3) -> 46664 | BI9: =IF($B$3="月",EDATE($DG$3,50),$DG$3+50*$DF$3) -> 46671 | BJ9: =IF($B$3="月",EDATE($DG$3,51),$DG$3+51*$DF$3) -> 46678 | BK9: =IF($B$3="月",EDATE($DG$3,52),$DG$3+52*$DF$3) -> 46685 | BL9: =IF($B$3="月",EDATE($DG$3,53),$DG$3+53*$DF$3) -> 46692 | BM9: =IF($B$3="月",EDATE($DG$3,54),$DG$3+54*$DF$3) -> 46699 | BN9: =IF($B$3="月",EDATE($DG$3,55),$DG$3+55*$DF$3) -> 46706 | BO9: =IF($B$3="月",EDATE($DG$3,56),$DG$3+56*$DF$3) -> 46713 | BP9: =IF($B$3="月",EDATE($DG$3,57),$DG$3+57*$DF$3) -> 46720 | BQ9: =IF($B$3="月",EDATE($DG$3,58),$DG$3+58*$DF$3) -> 46727 | BR9: =IF($B$3="月",EDATE($DG$3,59),$DG$3+59*$DF$3) -> 46734 | BS9: =IF($B$3="月",EDATE($DG$3,60),$DG$3+60*$DF$3) -> 46741 | BT9: =IF($B$3="月",EDATE($DG$3,61),$DG$3+61*$DF$3) -> 46748 | BU9: =IF($B$3="月",EDATE($DG$3,62),$DG$3+62*$DF$3) -> 46755 | BV9: =IF($B$3="月",EDATE($DG$3,63),$DG$3+63*$DF$3) -> 46762 | BW9: =IF($B$3="月",EDATE($DG$3,64),$DG$3+64*$DF$3) -> 46769 | BX9: =IF($B$3="月",EDATE($DG$3,65),$DG$3+65*$DF$3) -> 46776 | BY9: =IF($B$3="月",EDATE($DG$3,66),$DG$3+66*$DF$3) -> 46783 | BZ9: =IF($B$3="月",EDATE($DG$3,67),$DG$3+67*$DF$3) -> 46790 | CA9: =IF($B$3="月",EDATE($DG$3,68),$DG$3+68*$DF$3) -> 46797 | CB9: =IF($B$3="月",EDATE($DG$3,69),$DG$3+69*$DF$3) -> 46804 | CC9: =IF($B$3="月",EDATE($DG$3,70),$DG$3+70*$DF$3) -> 46811 | CD9: =IF($B$3="月",EDATE($DG$3,71),$DG$3+71*$DF$3) -> 46818 | CE9: =IF($B$3="月",EDATE($DG$3,72),$DG$3+72*$DF$3) -> 46825 | CF9: =IF($B$3="月",EDATE($DG$3,73),$DG$3+73*$DF$3) -> 46832 | CG9: =IF($B$3="月",EDATE($DG$3,74),$DG$3+74*$DF$3) -> 46839 | CH9: =IF($B$3="月",EDATE($DG$3,75),$DG$3+75*$DF$3) -> 46846 | CI9: =IF($B$3="月",EDATE($DG$3,76),$DG$3+76*$DF$3) -> 46853 | CJ9: =IF($B$3="月",EDATE($DG$3,77),$DG$3+77*$DF$3) -> 46860 | CK9: =IF($B$3="月",EDATE($DG$3,78),$DG$3+78*$DF$3) -> 46867 | CL9: =IF($B$3="月",EDATE($DG$3,79),$DG$3+79*$DF$3) -> 46874 | CM9: =IF($B$3="月",EDATE($DG$3,80),$DG$3+80*$DF$3) -> 46881 | CN9: =IF($B$3="月",EDATE($DG$3,81),$DG$3+81*$DF$3) -> 46888 | CO9: =IF($B$3="月",EDATE($DG$3,82),$DG$3+82*$DF$3) -> 46895 | CP9: =IF($B$3="月",EDATE($DG$3,83),$DG$3+83*$DF$3) -> 46902 | CQ9: =IF($B$3="月",EDATE($DG$3,84),$DG$3+84*$DF$3) -> 46909 | CR9: =IF($B$3="月",EDATE($DG$3,85),$DG$3+85*$DF$3) -> 46916 | CS9: =IF($B$3="月",EDATE($DG$3,86),$DG$3+86*$DF$3) -> 46923 | CT9: =IF($B$3="月",EDATE($DG$3,87),$DG$3+87*$DF$3) -> 46930 | CU9: =IF($B$3="月",EDATE($DG$3,88),$DG$3+88*$DF$3) -> 46937 | CV9: =IF($B$3="月",EDATE($DG$3,89),$DG$3+89*$DF$3) -> 46944 | CW9: =IF($B$3="月",EDATE($DG$3,90),$DG$3+90*$DF$3) -> 46951 | CX9: =IF($B$3="月",EDATE($DG$3,91),$DG$3+91*$DF$3) -> 46958 | CY9: =IF($B$3="月",EDATE($DG$3,92),$DG$3+92*$DF$3) -> 46965 | CZ9: =IF($B$3="月",EDATE($DG$3,93),$DG$3+93*$DF$3) -> 46972 | DA9: =IF($B$3="月",EDATE($DG$3,94),$DG$3+94*$DF$3) -> 46979 | DB9: =IF($B$3="月",EDATE($DG$3,95),$DG$3+95*$DF$3) -> 46986
A10: =IF($DC10="","",IF(AND(INDEX(排期计算!$A$10:$A$109,$DC10)="",NOT(ISNUMBER(INDEX(排期计算!$A$10:$A$109,$DC10)))),"",INDEX(排期计算!$A$10:$A$109,$DC10))) -> 1 | B10: =IF($DC10="","",REPT(" ",$DD10-1)&INDEX(排期计算!$B$10:$B$109,$DC10)) -> 设计开发 | C10: =IF($DC10="","",IF(AND(INDEX(排期计算!$M$10:$M$109,$DC10)="",NOT(ISNUMBER(INDEX(排期计算!$M$10:$M$109,$DC10)))),"",INDEX(排期计算!$M$10:$M$109,$DC10))) -> 46321 | D10: =IF($DC10="","",IF(AND(INDEX(排期计算!$N$10:$N$109,$DC10)="",NOT(ISNUMBER(INDEX(排期计算!$N$10:$N$109,$DC10)))),"",INDEX(排期计算!$N$10:$N$109,$DC10))) -> 46330 | E10: =IF(OR($C10="",$D10=""),"",IF($J10="里程碑",0,NETWORKDAYS($C10,$D10))) -> 8 | F10: =IF($DC10="","",IF(AND(INDEX(排期计算!$O$10:$O$109,$DC10)="",NOT(ISNUMBER(INDEX(排期计算!$O$10:$O$109,$DC10)))),"",INDEX(排期计算!$O$10:$O$109,$DC10))) -> 0.41 | G10: =IF($A10="","",IF(OR($C10="",$D10=""),"未排期",IF($F10>=1,"已完成",IF($D10<$B$4,"逾期",IF($C10>$B$4,"未开始","进行中"))))) -> 进行中 | H10: =IF($DC10="","",IF(AND(INDEX(排期计算!$C$10:$C$109,$DC10)="",NOT(ISNUMBER(INDEX(排期计算!$C$10:$C$109,$DC10)))),"",INDEX(排期计算!$C$10:$C$109,$DC10))) -> 张工 | I10: =IF($DC10="","",IF(AND(INDEX(排期计算!$H$10:$H$109,$DC10)="",NOT(ISNUMBER(INDEX(排期计算!$H$10:$H$109,$DC10)))),"",INDEX(排期计算!$H$10:$H$109,$DC10))) | J10: =IF($DC10="","",IF(AND(INDEX(排期计算!$K$10:$K$109,$DC10)="",NOT(ISNUMBER(INDEX(排期计算!$K$10:$K$109,$DC10)))),"",INDEX(排期计算!$K$10:$K$109,$DC10))) -> 汇总 | K10: =IF(OR($A10="",$C10="",$D10="",$C10>K$6,$D10<K$9),"",IF($J10="里程碑","◆","")) | L10: =IF(OR($A10="",$C10="",$D10="",$C10>L$6,$D10<L$9),"",IF($J10="里程碑","◆","")) | M10: =IF(OR($A10="",$C10="",$D10="",$C10>M$6,$D10<M$9),"",IF($J10="里程碑","◆","")) | N10: =IF(OR($A10="",$C10="",$D10="",$C10>N$6,$D10<N$9),"",IF($J10="里程碑","◆","")) | O10: =IF(OR($A10="",$C10="",$D10="",$C10>O$6,$D10<O$9),"",IF($J10="里程碑","◆","")) | P10: =IF(OR($A10="",$C10="",$D10="",$C10>P$6,$D10<P$9),"",IF($J10="里程碑","◆","")) | Q10: =IF(OR($A10="",$C10="",$D10="",$C10>Q$6,$D10<Q$9),"",IF($J10="里程碑","◆","")) | R10: =IF(OR($A10="",$C10="",$D10="",$C10>R$6,$D10<R$9),"",IF($J10="里程碑","◆","")) | ... DB10: =IF(OR($A10="",$C10="",$D10="",$C10>DB$6,$D10<DB$9),"",IF($J10="里程碑","◆","")) | DC10: =IF(ROW()-9>$DH$3,"",MATCH(ROW()-9,排期计算!$U$10:$U$109,0)) -> 1 | DD10: =IF($DC10="","",INDEX(排期计算!$L$10:$L$109,$DC10)) -> 1
A11: =IF($DC11="","",IF(AND(INDEX(排期计算!$A$10:$A$109,$DC11)="",NOT(ISNUMBER(INDEX(排期计算!$A$10:$A$109,$DC11)))),"",INDEX(排期计算!$A$10:$A$109,$DC11))) -> 1.1 | B11: =IF($DC11="","",REPT(" ",$DD11-1)&INDEX(排期计算!$B$10:$B$109,$DC11)) -> 需求与接口确认 | C11: =IF($DC11="","",IF(AND(INDEX(排期计算!$M$10:$M$109,$DC11)="",NOT(ISNUMBER(INDEX(排期计算!$M$10:$M$109,$DC11)))),"",INDEX(排期计算!$M$10:$M$109,$DC11))) -> 46321 | D11: =IF($DC11="","",IF(AND(INDEX(排期计算!$N$10:$N$109,$DC11)="",NOT(ISNUMBER(INDEX(排期计算!$N$10:$N$109,$DC11)))),"",INDEX(排期计算!$N$10:$N$109,$DC11))) -> 46322 | E11: =IF(OR($C11="",$D11=""),"",IF($J11="里程碑",0,NETWORKDAYS($C11,$D11))) -> 2 | F11: =IF($DC11="","",IF(AND(INDEX(排期计算!$O$10:$O$109,$DC11)="",NOT(ISNUMBER(INDEX(排期计算!$O$10:$O$109,$DC11)))),"",INDEX(排期计算!$O$10:$O$109,$DC11))) -> 1 | G11: =IF($A11="","",IF(OR($C11="",$D11=""),"未排期",IF($F11>=1,"已完成",IF($D11<$B$4,"逾期",IF($C11>$B$4,"未开始","进行中"))))) -> 已完成 | H11: =IF($DC11="","",IF(AND(INDEX(排期计算!$C$10:$C$109,$DC11)="",NOT(ISNUMBER(INDEX(排期计算!$C$10:$C$109,$DC11)))),"",INDEX(排期计算!$C$10:$C$109,$DC11))) -> 张工 | I11: =IF($DC11="","",IF(AND(INDEX(排期计算!$H$10:$H$109,$DC11)="",NOT(ISNUMBER(INDEX(排期计算!$H$10:$H$109,$DC11)))),"",INDEX(排期计算!$H$10:$H$109,$DC11))) | J11: =IF($DC11="","",IF(AND(INDEX(排期计算!$K$10:$K$109,$DC11)="",NOT(ISNUMBER(INDEX(排期计算!$K$10:$K$109,$DC11)))),"",INDEX(排期计算!$K$10:$K$109,$DC11))) -> 普通任务 | K11: =IF(OR($A11="",$C11="",$D11="",$C11>K$6,$D11<K$9),"",IF($J11="里程碑","◆","")) | L11: =IF(OR($A11="",$C11="",$D11="",$C11>L$6,$D11<L$9),"",IF($J11="里程碑","◆","")) | M11: =IF(OR($A11="",$C11="",$D11="",$C11>M$6,$D11<M$9),"",IF($J11="里程碑","◆","")) | N11: =IF(OR($A11="",$C11="",$D11="",$C11>N$6,$D11<N$9),"",IF($J11="里程碑","◆","")) | O11: =IF(OR($A11="",$C11="",$D11="",$C11>O$6,$D11<O$9),"",IF($J11="里程碑","◆","")) | P11: =IF(OR($A11="",$C11="",$D11="",$C11>P$6,$D11<P$9),"",IF($J11="里程碑","◆","")) | Q11: =IF(OR($A11="",$C11="",$D11="",$C11>Q$6,$D11<Q$9),"",IF($J11="里程碑","◆","")) | R11: =IF(OR($A11="",$C11="",$D11="",$C11>R$6,$D11<R$9),"",IF($J11="里程碑","◆","")) | ... DB11: =IF(OR($A11="",$C11="",$D11="",$C11>DB$6,$D11<DB$9),"",IF($J11="里程碑","◆","")) | DC11: =IF(ROW()-9>$DH$3,"",MATCH(ROW()-9,排期计算!$U$10:$U$109,0)) -> 2 | DD11: =IF($DC11="","",INDEX(排期计算!$L$10:$L$109,$DC11)) -> 2
A12: =IF($DC12="","",IF(AND(INDEX(排期计算!$A$10:$A$109,$DC12)="",NOT(ISNUMBER(INDEX(排期计算!$A$10:$A$109,$DC12)))),"",INDEX(排期计算!$A$10:$A$109,$DC12))) -> 1.2 | B12: =IF($DC12="","",REPT(" ",$DD12-1)&INDEX(排期计算!$B$10:$B$109,$DC12)) -> 结构方案及设计评审 | C12: =IF($DC12="","",IF(AND(INDEX(排期计算!$M$10:$M$109,$DC12)="",NOT(ISNUMBER(INDEX(排期计算!$M$10:$M$109,$DC12)))),"",INDEX(排期计算!$M$10:$M$109,$DC12))) -> 46323 | D12: =IF($DC12="","",IF(AND(INDEX(排期计算!$N$10:$N$109,$DC12)="",NOT(ISNUMBER(INDEX(排期计算!$N$10:$N$109,$DC12)))),"",INDEX(排期计算!$N$10:$N$109,$DC12))) -> 46329 | E12: =IF(OR($C12="",$D12=""),"",IF($J12="里程碑",0,NETWORKDAYS($C12,$D12))) -> 5 | F12: =IF($DC12="","",IF(AND(INDEX(排期计算!$O$10:$O$109,$DC12)="",NOT(ISNUMBER(INDEX(排期计算!$O$10:$O$109,$DC12)))),"",INDEX(排期计算!$O$10:$O$109,$DC12))) -> 0.25 | G12: =IF($A12="","",IF(OR($C12="",$D12=""),"未排期",IF($F12>=1,"已完成",IF($D12<$B$4,"逾期",IF($C12>$B$4,"未开始","进行中"))))) -> 未开始 | H12: =IF($DC12="","",IF(AND(INDEX(排期计算!$C$10:$C$109,$DC12)="",NOT(ISNUMBER(INDEX(排期计算!$C$10:$C$109,$DC12)))),"",INDEX(排期计算!$C$10:$C$109,$DC12))) -> 张工 | I12: =IF($DC12="","",IF(AND(INDEX(排期计算!$H$10:$H$109,$DC12)="",NOT(ISNUMBER(INDEX(排期计算!$H$10:$H$109,$DC12)))),"",INDEX(排期计算!$H$10:$H$109,$DC12))) -> 1.1 | J12: =IF($DC12="","",IF(AND(INDEX(排期计算!$K$10:$K$109,$DC12)="",NOT(ISNUMBER(INDEX(排期计算!$K$10:$K$109,$DC12)))),"",INDEX(排期计算!$K$10:$K$109,$DC12))) -> 普通任务 | K12: =IF(OR($A12="",$C12="",$D12="",$C12>K$6,$D12<K$9),"",IF($J12="里程碑","◆","")) | L12: =IF(OR($A12="",$C12="",$D12="",$C12>L$6,$D12<L$9),"",IF($J12="里程碑","◆","")) | M12: =IF(OR($A12="",$C12="",$D12="",$C12>M$6,$D12<M$9),"",IF($J12="里程碑","◆","")) | N12: =IF(OR($A12="",$C12="",$D12="",$C12>N$6,$D12<N$9),"",IF($J12="里程碑","◆","")) | O12: =IF(OR($A12="",$C12="",$D12="",$C12>O$6,$D12<O$9),"",IF($J12="里程碑","◆","")) | P12: =IF(OR($A12="",$C12="",$D12="",$C12>P$6,$D12<P$9),"",IF($J12="里程碑","◆","")) | Q12: =IF(OR($A12="",$C12="",$D12="",$C12>Q$6,$D12<Q$9),"",IF($J12="里程碑","◆","")) | R12: =IF(OR($A12="",$C12="",$D12="",$C12>R$6,$D12<R$9),"",IF($J12="里程碑","◆","")) | ... DB12: =IF(OR($A12="",$C12="",$D12="",$C12>DB$6,$D12<DB$9),"",IF($J12="里程碑","◆","")) | DC12: =IF(ROW()-9>$DH$3,"",MATCH(ROW()-9,排期计算!$U$10:$U$109,0)) -> 3 | DD12: =IF($DC12="","",INDEX(排期计算!$L$10:$L$109,$DC12)) -> 2
A13: =IF($DC13="","",IF(AND(INDEX(排期计算!$A$10:$A$109,$DC13)="",NOT(ISNUMBER(INDEX(排期计算!$A$10:$A$109,$DC13)))),"",INDEX(排期计算!$A$10:$A$109,$DC13))) -> 1.3 | B13: =IF($DC13="","",REPT(" ",$DD13-1)&INDEX(排期计算!$B$10:$B$109,$DC13)) -> 客户认可 | C13: =IF($DC13="","",IF(AND(INDEX(排期计算!$M$10:$M$109,$DC13)="",NOT(ISNUMBER(INDEX(排期计算!$M$10:$M$109,$DC13)))),"",INDEX(排期计算!$M$10:$M$109,$DC13))) -> 46330 | D13: =IF($DC13="","",IF(AND(INDEX(排期计算!$N$10:$N$109,$DC13)="",NOT(ISNUMBER(INDEX(排期计算!$N$10:$N$109,$DC13)))),"",INDEX(排期计算!$N$10:$N$109,$DC13))) -> 46330 | E13: =IF(OR($C13="",$D13=""),"",IF($J13="里程碑",0,NETWORKDAYS($C13,$D13))) -> 0 | F13: =IF($DC13="","",IF(AND(INDEX(排期计算!$O$10:$O$109,$DC13)="",NOT(ISNUMBER(INDEX(排期计算!$O$10:$O$109,$DC13)))),"",INDEX(排期计算!$O$10:$O$109,$DC13))) -> 0 | G13: =IF($A13="","",IF(OR($C13="",$D13=""),"未排期",IF($F13>=1,"已完成",IF($D13<$B$4,"逾期",IF($C13>$B$4,"未开始","进行中"))))) -> 未开始 | H13: =IF($DC13="","",IF(AND(INDEX(排期计算!$C$10:$C$109,$DC13)="",NOT(ISNUMBER(INDEX(排期计算!$C$10:$C$109,$DC13)))),"",INDEX(排期计算!$C$10:$C$109,$DC13))) -> 张工 | I13: =IF($DC13="","",IF(AND(INDEX(排期计算!$H$10:$H$109,$DC13)="",NOT(ISNUMBER(INDEX(排期计算!$H$10:$H$109,$DC13)))),"",INDEX(排期计算!$H$10:$H$109,$DC13))) -> 1.2 | J13: =IF($DC13="","",IF(AND(INDEX(排期计算!$K$10:$K$109,$DC13)="",NOT(ISNUMBER(INDEX(排期计算!$K$10:$K$109,$DC13)))),"",INDEX(排期计算!$K$10:$K$109,$DC13))) -> 里程碑 | K13: =IF(OR($A13="",$C13="",$D13="",$C13>K$6,$D13<K$9),"",IF($J13="里程碑","◆","")) | L13: =IF(OR($A13="",$C13="",$D13="",$C13>L$6,$D13<L$9),"",IF($J13="里程碑","◆","")) -> ◆ | M13: =IF(OR($A13="",$C13="",$D13="",$C13>M$6,$D13<M$9),"",IF($J13="里程碑","◆","")) | N13: =IF(OR($A13="",$C13="",$D13="",$C13>N$6,$D13<N$9),"",IF($J13="里程碑","◆","")) | O13: =IF(OR($A13="",$C13="",$D13="",$C13>O$6,$D13<O$9),"",IF($J13="里程碑","◆","")) | P13: =IF(OR($A13="",$C13="",$D13="",$C13>P$6,$D13<P$9),"",IF($J13="里程碑","◆","")) | Q13: =IF(OR($A13="",$C13="",$D13="",$C13>Q$6,$D13<Q$9),"",IF($J13="里程碑","◆","")) | R13: =IF(OR($A13="",$C13="",$D13="",$C13>R$6,$D13<R$9),"",IF($J13="里程碑","◆","")) | ... DB13: =IF(OR($A13="",$C13="",$D13="",$C13>DB$6,$D13<DB$9),"",IF($J13="里程碑","◆","")) | DC13: =IF(ROW()-9>$DH$3,"",MATCH(ROW()-9,排期计算!$U$10:$U$109,0)) -> 4 | DD13: =IF($DC13="","",INDEX(排期计算!$L$10:$L$109,$DC13)) -> 2
A14: =IF($DC14="","",IF(AND(INDEX(排期计算!$A$10:$A$109,$DC14)="",NOT(ISNUMBER(INDEX(排期计算!$A$10:$A$109,$DC14)))),"",INDEX(排期计算!$A$10:$A$109,$DC14))) -> 2 | B14: =IF($DC14="","",REPT(" ",$DD14-1)&INDEX(排期计算!$B$10:$B$109,$DC14)) -> 试制验证 | C14: =IF($DC14="","",IF(AND(INDEX(排期计算!$M$10:$M$109,$DC14)="",NOT(ISNUMBER(INDEX(排期计算!$M$10:$M$109,$DC14)))),"",INDEX(排期计算!$M$10:$M$109,$DC14))) -> 46331 | D14: =IF($DC14="","",IF(AND(INDEX(排期计算!$N$10:$N$109,$DC14)="",NOT(ISNUMBER(INDEX(排期计算!$N$10:$N$109,$DC14)))),"",INDEX(排期计算!$N$10:$N$109,$DC14))) -> 46344 | E14: =IF(OR($C14="",$D14=""),"",IF($J14="里程碑",0,NETWORKDAYS($C14,$D14))) -> 10 | F14: =IF($DC14="","",IF(AND(INDEX(排期计算!$O$10:$O$109,$DC14)="",NOT(ISNUMBER(INDEX(排期计算!$O$10:$O$109,$DC14)))),"",INDEX(排期计算!$O$10:$O$109,$DC14))) -> 0 | G14: =IF($A14="","",IF(OR($C14="",$D14=""),"未排期",IF($F14>=1,"已完成",IF($D14<$B$4,"逾期",IF($C14>$B$4,"未开始","进行中"))))) -> 未开始 | H14: =IF($DC14="","",IF(AND(INDEX(排期计算!$C$10:$C$109,$DC14)="",NOT(ISNUMBER(INDEX(排期计算!$C$10:$C$109,$DC14)))),"",INDEX(排期计算!$C$10:$C$109,$DC14))) -> 张工 | I14: =IF($DC14="","",IF(AND(INDEX(排期计算!$H$10:$H$109,$DC14)="",NOT(ISNUMBER(INDEX(排期计算!$H$10:$H$109,$DC14)))),"",INDEX(排期计算!$H$10:$H$109,$DC14))) | J14: =IF($DC14="","",IF(AND(INDEX(排期计算!$K$10:$K$109,$DC14)="",NOT(ISNUMBER(INDEX(排期计算!$K$10:$K$109,$DC14)))),"",INDEX(排期计算!$K$10:$K$109,$DC14))) -> 汇总 | K14: =IF(OR($A14="",$C14="",$D14="",$C14>K$6,$D14<K$9),"",IF($J14="里程碑","◆","")) | L14: =IF(OR($A14="",$C14="",$D14="",$C14>L$6,$D14<L$9),"",IF($J14="里程碑","◆","")) | M14: =IF(OR($A14="",$C14="",$D14="",$C14>M$6,$D14<M$9),"",IF($J14="里程碑","◆","")) | N14: =IF(OR($A14="",$C14="",$D14="",$C14>N$6,$D14<N$9),"",IF($J14="里程碑","◆","")) | O14: =IF(OR($A14="",$C14="",$D14="",$C14>O$6,$D14<O$9),"",IF($J14="里程碑","◆","")) | P14: =IF(OR($A14="",$C14="",$D14="",$C14>P$6,$D14<P$9),"",IF($J14="里程碑","◆","")) | Q14: =IF(OR($A14="",$C14="",$D14="",$C14>Q$6,$D14<Q$9),"",IF($J14="里程碑","◆","")) | R14: =IF(OR($A14="",$C14="",$D14="",$C14>R$6,$D14<R$9),"",IF($J14="里程碑","◆","")) | ... DB14: =IF(OR($A14="",$C14="",$D14="",$C14>DB$6,$D14<DB$9),"",IF($J14="里程碑","◆","")) | DC14: =IF(ROW()-9>$DH$3,"",MATCH(ROW()-9,排期计算!$U$10:$U$109,0)) -> 5 | DD14: =IF($DC14="","",INDEX(排期计算!$L$10:$L$109,$DC14)) -> 1
A15: =IF($DC15="","",IF(AND(INDEX(排期计算!$A$10:$A$109,$DC15)="",NOT(ISNUMBER(INDEX(排期计算!$A$10:$A$109,$DC15)))),"",INDEX(排期计算!$A$10:$A$109,$DC15))) -> 2.1 | B15: =IF($DC15="","",REPT(" ",$DD15-1)&INDEX(排期计算!$B$10:$B$109,$DC15)) -> 样件制造与试验 | C15: =IF($DC15="","",IF(AND(INDEX(排期计算!$M$10:$M$109,$DC15)="",NOT(ISNUMBER(INDEX(排期计算!$M$10:$M$109,$DC15)))),"",INDEX(排期计算!$M$10:$M$109,$DC15))) -> 46331 | D15: =IF($DC15="","",IF(AND(INDEX(排期计算!$N$10:$N$109,$DC15)="",NOT(ISNUMBER(INDEX(排期计算!$N$10:$N$109,$DC15)))),"",INDEX(排期计算!$N$10:$N$109,$DC15))) -> 46344 | E15: =IF(OR($C15="",$D15=""),"",IF($J15="里程碑",0,NETWORKDAYS($C15,$D15))) -> 10 | F15: =IF($DC15="","",IF(AND(INDEX(排期计算!$O$10:$O$109,$DC15)="",NOT(ISNUMBER(INDEX(排期计算!$O$10:$O$109,$DC15)))),"",INDEX(排期计算!$O$10:$O$109,$DC15))) -> 0 | G15: =IF($A15="","",IF(OR($C15="",$D15=""),"未排期",IF($F15>=1,"已完成",IF($D15<$B$4,"逾期",IF($C15>$B$4,"未开始","进行中"))))) -> 未开始 | H15: =IF($DC15="","",IF(AND(INDEX(排期计算!$C$10:$C$109,$DC15)="",NOT(ISNUMBER(INDEX(排期计算!$C$10:$C$109,$DC15)))),"",INDEX(排期计算!$C$10:$C$109,$DC15))) -> 张工 | I15: =IF($DC15="","",IF(AND(INDEX(排期计算!$H$10:$H$109,$DC15)="",NOT(ISNUMBER(INDEX(排期计算!$H$10:$H$109,$DC15)))),"",INDEX(排期计算!$H$10:$H$109,$DC15))) -> 1.3 | J15: =IF($DC15="","",IF(AND(INDEX(排期计算!$K$10:$K$109,$DC15)="",NOT(ISNUMBER(INDEX(排期计算!$K$10:$K$109,$DC15)))),"",INDEX(排期计算!$K$10:$K$109,$DC15))) -> 普通任务 | K15: =IF(OR($A15="",$C15="",$D15="",$C15>K$6,$D15<K$9),"",IF($J15="里程碑","◆","")) | L15: =IF(OR($A15="",$C15="",$D15="",$C15>L$6,$D15<L$9),"",IF($J15="里程碑","◆","")) | M15: =IF(OR($A15="",$C15="",$D15="",$C15>M$6,$D15<M$9),"",IF($J15="里程碑","◆","")) | N15: =IF(OR($A15="",$C15="",$D15="",$C15>N$6,$D15<N$9),"",IF($J15="里程碑","◆","")) | O15: =IF(OR($A15="",$C15="",$D15="",$C15>O$6,$D15<O$9),"",IF($J15="里程碑","◆","")) | P15: =IF(OR($A15="",$C15="",$D15="",$C15>P$6,$D15<P$9),"",IF($J15="里程碑","◆","")) | Q15: =IF(OR($A15="",$C15="",$D15="",$C15>Q$6,$D15<Q$9),"",IF($J15="里程碑","◆","")) | R15: =IF(OR($A15="",$C15="",$D15="",$C15>R$6,$D15<R$9),"",IF($J15="里程碑","◆","")) | ... DB15: =IF(OR($A15="",$C15="",$D15="",$C15>DB$6,$D15<DB$9),"",IF($J15="里程碑","◆","")) | DC15: =IF(ROW()-9>$DH$3,"",MATCH(ROW()-9,排期计算!$U$10:$U$109,0)) -> 6 | DD15: =IF($DC15="","",INDEX(排期计算!$L$10:$L$109,$DC15)) -> 2
A16: =IF($DC16="","",IF(AND(INDEX(排期计算!$A$10:$A$109,$DC16)="",NOT(ISNUMBER(INDEX(排期计算!$A$10:$A$109,$DC16)))),"",INDEX(排期计算!$A$10:$A$109,$DC16))) -> 3 | B16: =IF($DC16="","",REPT(" ",$DD16-1)&INDEX(排期计算!$B$10:$B$109,$DC16)) -> 量产移交 | C16: =IF($DC16="","",IF(AND(INDEX(排期计算!$M$10:$M$109,$DC16)="",NOT(ISNUMBER(INDEX(排期计算!$M$10:$M$109,$DC16)))),"",INDEX(排期计算!$M$10:$M$109,$DC16))) -> 46345 | D16: =IF($DC16="","",IF(AND(INDEX(排期计算!$N$10:$N$109,$DC16)="",NOT(ISNUMBER(INDEX(排期计算!$N$10:$N$109,$DC16)))),"",INDEX(排期计算!$N$10:$N$109,$DC16))) -> 46345 | E16: =IF(OR($C16="",$D16=""),"",IF($J16="里程碑",0,NETWORKDAYS($C16,$D16))) -> 0 | F16: =IF($DC16="","",IF(AND(INDEX(排期计算!$O$10:$O$109,$DC16)="",NOT(ISNUMBER(INDEX(排期计算!$O$10:$O$109,$DC16)))),"",INDEX(排期计算!$O$10:$O$109,$DC16))) -> 0 | G16: =IF($A16="","",IF(OR($C16="",$D16=""),"未排期",IF($F16>=1,"已完成",IF($D16<$B$4,"逾期",IF($C16>$B$4,"未开始","进行中"))))) -> 未开始 | H16: =IF($DC16="","",IF(AND(INDEX(排期计算!$C$10:$C$109,$DC16)="",NOT(ISNUMBER(INDEX(排期计算!$C$10:$C$109,$DC16)))),"",INDEX(排期计算!$C$10:$C$109,$DC16))) -> 张工 | I16: =IF($DC16="","",IF(AND(INDEX(排期计算!$H$10:$H$109,$DC16)="",NOT(ISNUMBER(INDEX(排期计算!$H$10:$H$109,$DC16)))),"",INDEX(排期计算!$H$10:$H$109,$DC16))) -> 2.1 | J16: =IF($DC16="","",IF(AND(INDEX(排期计算!$K$10:$K$109,$DC16)="",NOT(ISNUMBER(INDEX(排期计算!$K$10:$K$109,$DC16)))),"",INDEX(排期计算!$K$10:$K$109,$DC16))) -> 里程碑 | K16: =IF(OR($A16="",$C16="",$D16="",$C16>K$6,$D16<K$9),"",IF($J16="里程碑","◆","")) | L16: =IF(OR($A16="",$C16="",$D16="",$C16>L$6,$D16<L$9),"",IF($J16="里程碑","◆","")) | M16: =IF(OR($A16="",$C16="",$D16="",$C16>M$6,$D16<M$9),"",IF($J16="里程碑","◆","")) | N16: =IF(OR($A16="",$C16="",$D16="",$C16>N$6,$D16<N$9),"",IF($J16="里程碑","◆","")) -> ◆ | O16: =IF(OR($A16="",$C16="",$D16="",$C16>O$6,$D16<O$9),"",IF($J16="里程碑","◆","")) | P16: =IF(OR($A16="",$C16="",$D16="",$C16>P$6,$D16<P$9),"",IF($J16="里程碑","◆","")) | Q16: =IF(OR($A16="",$C16="",$D16="",$C16>Q$6,$D16<Q$9),"",IF($J16="里程碑","◆","")) | R16: =IF(OR($A16="",$C16="",$D16="",$C16>R$6,$D16<R$9),"",IF($J16="里程碑","◆","")) | ... DB16: =IF(OR($A16="",$C16="",$D16="",$C16>DB$6,$D16<DB$9),"",IF($J16="里程碑","◆","")) | DC16: =IF(ROW()-9>$DH$3,"",MATCH(ROW()-9,排期计算!$U$10:$U$109,0)) -> 7 | DD16: =IF($DC16="","",INDEX(排期计算!$L$10:$L$109,$DC16)) -> 1
A17: =IF($DC17="","",IF(AND(INDEX(排期计算!$A$10:$A$109,$DC17)="",NOT(ISNUMBER(INDEX(排期计算!$A$10:$A$109,$DC17)))),"",INDEX(排期计算!$A$10:$A$109,$DC17))) | B17: =IF($DC17="","",REPT(" ",$DD17-1)&INDEX(排期计算!$B$10:$B$109,$DC17)) | C17: =IF($DC17="","",IF(AND(INDEX(排期计算!$M$10:$M$109,$DC17)="",NOT(ISNUMBER(INDEX(排期计算!$M$10:$M$109,$DC17)))),"",INDEX(排期计算!$M$10:$M$109,$DC17))) | D17: =IF($DC17="","",IF(AND(INDEX(排期计算!$N$10:$N$109,$DC17)="",NOT(ISNUMBER(INDEX(排期计算!$N$10:$N$109,$DC17)))),"",INDEX(排期计算!$N$10:$N$109,$DC17))) | E17: =IF(OR($C17="",$D17=""),"",IF($J17="里程碑",0,NETWORKDAYS($C17,$D17))) | F17: =IF($DC17="","",IF(AND(INDEX(排期计算!$O$10:$O$109,$DC17)="",NOT(ISNUMBER(INDEX(排期计算!$O$10:$O$109,$DC17)))),"",INDEX(排期计算!$O$10:$O$109,$DC17))) | G17: =IF($A17="","",IF(OR($C17="",$D17=""),"未排期",IF($F17>=1,"已完成",IF($D17<$B$4,"逾期",IF($C17>$B$4,"未开始","进行中"))))) | H17: =IF($DC17="","",IF(AND(INDEX(排期计算!$C$10:$C$109,$DC17)="",NOT(ISNUMBER(INDEX(排期计算!$C$10:$C$109,$DC17)))),"",INDEX(排期计算!$C$10:$C$109,$DC17))) | I17: =IF($DC17="","",IF(AND(INDEX(排期计算!$H$10:$H$109,$DC17)="",NOT(ISNUMBER(INDEX(排期计算!$H$10:$H$109,$DC17)))),"",INDEX(排期计算!$H$10:$H$109,$DC17))) | J17: =IF($DC17="","",IF(AND(INDEX(排期计算!$K$10:$K$109,$DC17)="",NOT(ISNUMBER(INDEX(排期计算!$K$10:$K$109,$DC17)))),"",INDEX(排期计算!$K$10:$K$109,$DC17))) | K17: =IF(OR($A17="",$C17="",$D17="",$C17>K$6,$D17<K$9),"",IF($J17="里程碑","◆","")) | L17: =IF(OR($A17="",$C17="",$D17="",$C17>L$6,$D17<L$9),"",IF($J17="里程碑","◆","")) | M17: =IF(OR($A17="",$C17="",$D17="",$C17>M$6,$D17<M$9),"",IF($J17="里程碑","◆","")) | N17: =IF(OR($A17="",$C17="",$D17="",$C17>N$6,$D17<N$9),"",IF($J17="里程碑","◆","")) | O17: =IF(OR($A17="",$C17="",$D17="",$C17>O$6,$D17<O$9),"",IF($J17="里程碑","◆","")) | P17: =IF(OR($A17="",$C17="",$D17="",$C17>P$6,$D17<P$9),"",IF($J17="里程碑","◆","")) | Q17: =IF(OR($A17="",$C17="",$D17="",$C17>Q$6,$D17<Q$9),"",IF($J17="里程碑","◆","")) | R17: =IF(OR($A17="",$C17="",$D17="",$C17>R$6,$D17<R$9),"",IF($J17="里程碑","◆","")) | ... DB17: =IF(OR($A17="",$C17="",$D17="",$C17>DB$6,$D17<DB$9),"",IF($J17="里程碑","◆","")) | DC17: =IF(ROW()-9>$DH$3,"",MATCH(ROW()-9,排期计算!$U$10:$U$109,0)) | DD17: =IF($DC17="","",INDEX(排期计算!$L$10:$L$109,$DC17))
A18: =IF($DC18="","",IF(AND(INDEX(排期计算!$A$10:$A$109,$DC18)="",NOT(ISNUMBER(INDEX(排期计算!$A$10:$A$109,$DC18)))),"",INDEX(排期计算!$A$10:$A$109,$DC18))) | B18: =IF($DC18="","",REPT(" ",$DD18-1)&INDEX(排期计算!$B$10:$B$109,$DC18)) | C18: =IF($DC18="","",IF(AND(INDEX(排期计算!$M$10:$M$109,$DC18)="",NOT(ISNUMBER(INDEX(排期计算!$M$10:$M$109,$DC18)))),"",INDEX(排期计算!$M$10:$M$109,$DC18))) | D18: =IF($DC18="","",IF(AND(INDEX(排期计算!$N$10:$N$109,$DC18)="",NOT(ISNUMBER(INDEX(排期计算!$N$10:$N$109,$DC18)))),"",INDEX(排期计算!$N$10:$N$109,$DC18))) | E18: =IF(OR($C18="",$D18=""),"",IF($J18="里程碑",0,NETWORKDAYS($C18,$D18))) | F18: =IF($DC18="","",IF(AND(INDEX(排期计算!$O$10:$O$109,$DC18)="",NOT(ISNUMBER(INDEX(排期计算!$O$10:$O$109,$DC18)))),"",INDEX(排期计算!$O$10:$O$109,$DC18))) | G18: =IF($A18="","",IF(OR($C18="",$D18=""),"未排期",IF($F18>=1,"已完成",IF($D18<$B$4,"逾期",IF($C18>$B$4,"未开始","进行中"))))) | H18: =IF($DC18="","",IF(AND(INDEX(排期计算!$C$10:$C$109,$DC18)="",NOT(ISNUMBER(INDEX(排期计算!$C$10:$C$109,$DC18)))),"",INDEX(排期计算!$C$10:$C$109,$DC18))) | I18: =IF($DC18="","",IF(AND(INDEX(排期计算!$H$10:$H$109,$DC18)="",NOT(ISNUMBER(INDEX(排期计算!$H$10:$H$109,$DC18)))),"",INDEX(排期计算!$H$10:$H$109,$DC18))) | J18: =IF($DC18="","",IF(AND(INDEX(排期计算!$K$10:$K$109,$DC18)="",NOT(ISNUMBER(INDEX(排期计算!$K$10:$K$109,$DC18)))),"",INDEX(排期计算!$K$10:$K$109,$DC18))) | K18: =IF(OR($A18="",$C18="",$D18="",$C18>K$6,$D18<K$9),"",IF($J18="里程碑","◆","")) | L18: =IF(OR($A18="",$C18="",$D18="",$C18>L$6,$D18<L$9),"",IF($J18="里程碑","◆","")) | M18: =IF(OR($A18="",$C18="",$D18="",$C18>M$6,$D18<M$9),"",IF($J18="里程碑","◆","")) | N18: =IF(OR($A18="",$C18="",$D18="",$C18>N$6,$D18<N$9),"",IF($J18="里程碑","◆","")) | O18: =IF(OR($A18="",$C18="",$D18="",$C18>O$6,$D18<O$9),"",IF($J18="里程碑","◆","")) | P18: =IF(OR($A18="",$C18="",$D18="",$C18>P$6,$D18<P$9),"",IF($J18="里程碑","◆","")) | Q18: =IF(OR($A18="",$C18="",$D18="",$C18>Q$6,$D18<Q$9),"",IF($J18="里程碑","◆","")) | R18: =IF(OR($A18="",$C18="",$D18="",$C18>R$6,$D18<R$9),"",IF($J18="里程碑","◆","")) | ... DB18: =IF(OR($A18="",$C18="",$D18="",$C18>DB$6,$D18<DB$9),"",IF($J18="里程碑","◆","")) | DC18: =IF(ROW()-9>$DH$3,"",MATCH(ROW()-9,排期计算!$U$10:$U$109,0)) | DD18: =IF($DC18="","",INDEX(排期计算!$L$10:$L$109,$DC18))
A19: =IF($DC19="","",IF(AND(INDEX(排期计算!$A$10:$A$109,$DC19)="",NOT(ISNUMBER(INDEX(排期计算!$A$10:$A$109,$DC19)))),"",INDEX(排期计算!$A$10:$A$109,$DC19))) | B19: =IF($DC19="","",REPT(" ",$DD19-1)&INDEX(排期计算!$B$10:$B$109,$DC19)) | C19: =IF($DC19="","",IF(AND(INDEX(排期计算!$M$10:$M$109,$DC19)="",NOT(ISNUMBER(INDEX(排期计算!$M$10:$M$109,$DC19)))),"",INDEX(排期计算!$M$10:$M$109,$DC19))) | D19: =IF($DC19="","",IF(AND(INDEX(排期计算!$N$10:$N$109,$DC19)="",NOT(ISNUMBER(INDEX(排期计算!$N$10:$N$109,$DC19)))),"",INDEX(排期计算!$N$10:$N$109,$DC19))) | E19: =IF(OR($C19="",$D19=""),"",IF($J19="里程碑",0,NETWORKDAYS($C19,$D19))) | F19: =IF($DC19="","",IF(AND(INDEX(排期计算!$O$10:$O$109,$DC19)="",NOT(ISNUMBER(INDEX(排期计算!$O$10:$O$109,$DC19)))),"",INDEX(排期计算!$O$10:$O$109,$DC19))) | G19: =IF($A19="","",IF(OR($C19="",$D19=""),"未排期",IF($F19>=1,"已完成",IF($D19<$B$4,"逾期",IF($C19>$B$4,"未开始","进行中"))))) | H19: =IF($DC19="","",IF(AND(INDEX(排期计算!$C$10:$C$109,$DC19)="",NOT(ISNUMBER(INDEX(排期计算!$C$10:$C$109,$DC19)))),"",INDEX(排期计算!$C$10:$C$109,$DC19))) | I19: =IF($DC19="","",IF(AND(INDEX(排期计算!$H$10:$H$109,$DC19)="",NOT(ISNUMBER(INDEX(排期计算!$H$10:$H$109,$DC19)))),"",INDEX(排期计算!$H$10:$H$109,$DC19))) | J19: =IF($DC19="","",IF(AND(INDEX(排期计算!$K$10:$K$109,$DC19)="",NOT(ISNUMBER(INDEX(排期计算!$K$10:$K$109,$DC19)))),"",INDEX(排期计算!$K$10:$K$109,$DC19))) | K19: =IF(OR($A19="",$C19="",$D19="",$C19>K$6,$D19<K$9),"",IF($J19="里程碑","◆","")) | L19: =IF(OR($A19="",$C19="",$D19="",$C19>L$6,$D19<L$9),"",IF($J19="里程碑","◆","")) | M19: =IF(OR($A19="",$C19="",$D19="",$C19>M$6,$D19<M$9),"",IF($J19="里程碑","◆","")) | N19: =IF(OR($A19="",$C19="",$D19="",$C19>N$6,$D19<N$9),"",IF($J19="里程碑","◆","")) | O19: =IF(OR($A19="",$C19="",$D19="",$C19>O$6,$D19<O$9),"",IF($J19="里程碑","◆","")) | P19: =IF(OR($A19="",$C19="",$D19="",$C19>P$6,$D19<P$9),"",IF($J19="里程碑","◆","")) | Q19: =IF(OR($A19="",$C19="",$D19="",$C19>Q$6,$D19<Q$9),"",IF($J19="里程碑","◆","")) | R19: =IF(OR($A19="",$C19="",$D19="",$C19>R$6,$D19<R$9),"",IF($J19="里程碑","◆","")) | ... DB19: =IF(OR($A19="",$C19="",$D19="",$C19>DB$6,$D19<DB$9),"",IF($J19="里程碑","◆","")) | DC19: =IF(ROW()-9>$DH$3,"",MATCH(ROW()-9,排期计算!$U$10:$U$109,0)) | DD19: =IF($DC19="","",INDEX(排期计算!$L$10:$L$109,$DC19))
A20: =IF($DC20="","",IF(AND(INDEX(排期计算!$A$10:$A$109,$DC20)="",NOT(ISNUMBER(INDEX(排期计算!$A$10:$A$109,$DC20)))),"",INDEX(排期计算!$A$10:$A$109,$DC20))) | B20: =IF($DC20="","",REPT(" ",$DD20-1)&INDEX(排期计算!$B$10:$B$109,$DC20)) | C20: =IF($DC20="","",IF(AND(INDEX(排期计算!$M$10:$M$109,$DC20)="",NOT(ISNUMBER(INDEX(排期计算!$M$10:$M$109,$DC20)))),"",INDEX(排期计算!$M$10:$M$109,$DC20))) | D20: =IF($DC20="","",IF(AND(INDEX(排期计算!$N$10:$N$109,$DC20)="",NOT(ISNUMBER(INDEX(排期计算!$N$10:$N$109,$DC20)))),"",INDEX(排期计算!$N$10:$N$109,$DC20))) | E20: =IF(OR($C20="",$D20=""),"",IF($J20="里程碑",0,NETWORKDAYS($C20,$D20))) | F20: =IF($DC20="","",IF(AND(INDEX(排期计算!$O$10:$O$109,$DC20)="",NOT(ISNUMBER(INDEX(排期计算!$O$10:$O$109,$DC20)))),"",INDEX(排期计算!$O$10:$O$109,$DC20))) | G20: =IF($A20="","",IF(OR($C20="",$D20=""),"未排期",IF($F20>=1,"已完成",IF($D20<$B$4,"逾期",IF($C20>$B$4,"未开始","进行中"))))) | H20: =IF($DC20="","",IF(AND(INDEX(排期计算!$C$10:$C$109,$DC20)="",NOT(ISNUMBER(INDEX(排期计算!$C$10:$C$109,$DC20)))),"",INDEX(排期计算!$C$10:$C$109,$DC20))) | I20: =IF($DC20="","",IF(AND(INDEX(排期计算!$H$10:$H$109,$DC20)="",NOT(ISNUMBER(INDEX(排期计算!$H$10:$H$109,$DC20)))),"",INDEX(排期计算!$H$10:$H$109,$DC20))) | J20: =IF($DC20="","",IF(AND(INDEX(排期计算!$K$10:$K$109,$DC20)="",NOT(ISNUMBER(INDEX(排期计算!$K$10:$K$109,$DC20)))),"",INDEX(排期计算!$K$10:$K$109,$DC20))) | K20: =IF(OR($A20="",$C20="",$D20="",$C20>K$6,$D20<K$9),"",IF($J20="里程碑","◆","")) | L20: =IF(OR($A20="",$C20="",$D20="",$C20>L$6,$D20<L$9),"",IF($J20="里程碑","◆","")) | M20: =IF(OR($A20="",$C20="",$D20="",$C20>M$6,$D20<M$9),"",IF($J20="里程碑","◆","")) | N20: =IF(OR($A20="",$C20="",$D20="",$C20>N$6,$D20<N$9),"",IF($J20="里程碑","◆","")) | O20: =IF(OR($A20="",$C20="",$D20="",$C20>O$6,$D20<O$9),"",IF($J20="里程碑","◆","")) | P20: =IF(OR($A20="",$C20="",$D20="",$C20>P$6,$D20<P$9),"",IF($J20="里程碑","◆","")) | Q20: =IF(OR($A20="",$C20="",$D20="",$C20>Q$6,$D20<Q$9),"",IF($J20="里程碑","◆","")) | R20: =IF(OR($A20="",$C20="",$D20="",$C20>R$6,$D20<R$9),"",IF($J20="里程碑","◆","")) | ... DB20: =IF(OR($A20="",$C20="",$D20="",$C20>DB$6,$D20<DB$9),"",IF($J20="里程碑","◆","")) | DC20: =IF(ROW()-9>$DH$3,"",MATCH(ROW()-9,排期计算!$U$10:$U$109,0)) | DD20: =IF($DC20="","",INDEX(排期计算!$L$10:$L$109,$DC20))
A21: =IF($DC21="","",IF(AND(INDEX(排期计算!$A$10:$A$109,$DC21)="",NOT(ISNUMBER(INDEX(排期计算!$A$10:$A$109,$DC21)))),"",INDEX(排期计算!$A$10:$A$109,$DC21))) | B21: =IF($DC21="","",REPT(" ",$DD21-1)&INDEX(排期计算!$B$10:$B$109,$DC21)) | C21: =IF($DC21="","",IF(AND(INDEX(排期计算!$M$10:$M$109,$DC21)="",NOT(ISNUMBER(INDEX(排期计算!$M$10:$M$109,$DC21)))),"",INDEX(排期计算!$M$10:$M$109,$DC21))) | D21: =IF($DC21="","",IF(AND(INDEX(排期计算!$N$10:$N$109,$DC21)="",NOT(ISNUMBER(INDEX(排期计算!$N$10:$N$109,$DC21)))),"",INDEX(排期计算!$N$10:$N$109,$DC21))) | E21: =IF(OR($C21="",$D21=""),"",IF($J21="里程碑",0,NETWORKDAYS($C21,$D21))) | F21: =IF($DC21="","",IF(AND(INDEX(排期计算!$O$10:$O$109,$DC21)="",NOT(ISNUMBER(INDEX(排期计算!$O$10:$O$109,$DC21)))),"",INDEX(排期计算!$O$10:$O$109,$DC21))) | G21: =IF($A21="","",IF(OR($C21="",$D21=""),"未排期",IF($F21>=1,"已完成",IF($D21<$B$4,"逾期",IF($C21>$B$4,"未开始","进行中"))))) | H21: =IF($DC21="","",IF(AND(INDEX(排期计算!$C$10:$C$109,$DC21)="",NOT(ISNUMBER(INDEX(排期计算!$C$10:$C$109,$DC21)))),"",INDEX(排期计算!$C$10:$C$109,$DC21))) | I21: =IF($DC21="","",IF(AND(INDEX(排期计算!$H$10:$H$109,$DC21)="",NOT(ISNUMBER(INDEX(排期计算!$H$10:$H$109,$DC21)))),"",INDEX(排期计算!$H$10:$H$109,$DC21))) | J21: =IF($DC21="","",IF(AND(INDEX(排期计算!$K$10:$K$109,$DC21)="",NOT(ISNUMBER(INDEX(排期计算!$K$10:$K$109,$DC21)))),"",INDEX(排期计算!$K$10:$K$109,$DC21))) | K21: =IF(OR($A21="",$C21="",$D21="",$C21>K$6,$D21<K$9),"",IF($J21="里程碑","◆","")) | L21: =IF(OR($A21="",$C21="",$D21="",$C21>L$6,$D21<L$9),"",IF($J21="里程碑","◆","")) | M21: =IF(OR($A21="",$C21="",$D21="",$C21>M$6,$D21<M$9),"",IF($J21="里程碑","◆","")) | N21: =IF(OR($A21="",$C21="",$D21="",$C21>N$6,$D21<N$9),"",IF($J21="里程碑","◆","")) | O21: =IF(OR($A21="",$C21="",$D21="",$C21>O$6,$D21<O$9),"",IF($J21="里程碑","◆","")) | P21: =IF(OR($A21="",$C21="",$D21="",$C21>P$6,$D21<P$9),"",IF($J21="里程碑","◆","")) | Q21: =IF(OR($A21="",$C21="",$D21="",$C21>Q$6,$D21<Q$9),"",IF($J21="里程碑","◆","")) | R21: =IF(OR($A21="",$C21="",$D21="",$C21>R$6,$D21<R$9),"",IF($J21="里程碑","◆","")) | ... DB21: =IF(OR($A21="",$C21="",$D21="",$C21>DB$6,$D21<DB$9),"",IF($J21="里程碑","◆","")) | DC21: =IF(ROW()-9>$DH$3,"",MATCH(ROW()-9,排期计算!$U$10:$U$109,0)) | DD21: =IF($DC21="","",INDEX(排期计算!$L$10:$L$109,$DC21))
... A109: =IF($DC109="","",IF(AND(INDEX(排期计算!$A$10:$A$109,$DC109)="",NOT(ISNUMBER(INDEX(排期计算!$A$10:$A$109,$DC109)))),"",INDEX(排期计算!$A$10:$A$109,$DC109))) | B109: =IF($DC109="","",REPT(" ",$DD109-1)&INDEX(排期计算!$B$10:$B$109,$DC109)) | C109: =IF($DC109="","",IF(AND(INDEX(排期计算!$M$10:$M$109,$DC109)="",NOT(ISNUMBER(INDEX(排期计算!$M$10:$M$109,$DC109)))),"",INDEX(排期计算!$M$10:$M$109,$DC109))) | D109: =IF($DC109="","",IF(AND(INDEX(排期计算!$N$10:$N$109,$DC109)="",NOT(ISNUMBER(INDEX(排期计算!$N$10:$N$109,$DC109)))),"",INDEX(排期计算!$N$10:$N$109,$DC109))) | E109: =IF(OR($C109="",$D109=""),"",IF($J109="里程碑",0,NETWORKDAYS($C109,$D109))) | F109: =IF($DC109="","",IF(AND(INDEX(排期计算!$O$10:$O$109,$DC109)="",NOT(ISNUMBER(INDEX(排期计算!$O$10:$O$109,$DC109)))),"",INDEX(排期计算!$O$10:$O$109,$DC109))) | G109: =IF($A109="","",IF(OR($C109="",$D109=""),"未排期",IF($F109>=1,"已完成",IF($D109<$B$4,"逾期",IF($C109>$B$4,"未开始","进行中"))))) | H109: =IF($DC109="","",IF(AND(INDEX(排期计算!$C$10:$C$109,$DC109)="",NOT(ISNUMBER(INDEX(排期计算!$C$10:$C$109,$DC109)))),"",INDEX(排期计算!$C$10:$C$109,$DC109))) | I109: =IF($DC109="","",IF(AND(INDEX(排期计算!$H$10:$H$109,$DC109)="",NOT(ISNUMBER(INDEX(排期计算!$H$10:$H$109,$DC109)))),"",INDEX(排期计算!$H$10:$H$109,$DC109))) | J109: =IF($DC109="","",IF(AND(INDEX(排期计算!$K$10:$K$109,$DC109)="",NOT(ISNUMBER(INDEX(排期计算!$K$10:$K$109,$DC109)))),"",INDEX(排期计算!$K$10:$K$109,$DC109))) | K109: =IF(OR($A109="",$C109="",$D109="",$C109>K$6,$D109<K$9),"",IF($J109="里程碑","◆","")) | L109: =IF(OR($A109="",$C109="",$D109="",$C109>L$6,$D109<L$9),"",IF($J109="里程碑","◆","")) | M109: =IF(OR($A109="",$C109="",$D109="",$C109>M$6,$D109<M$9),"",IF($J109="里程碑","◆","")) | N109: =IF(OR($A109="",$C109="",$D109="",$C109>N$6,$D109<N$9),"",IF($J109="里程碑","◆","")) | O109: =IF(OR($A109="",$C109="",$D109="",$C109>O$6,$D109<O$9),"",IF($J109="里程碑","◆","")) | P109: =IF(OR($A109="",$C109="",$D109="",$C109>P$6,$D109<P$9),"",IF($J109="里程碑","◆","")) | Q109: =IF(OR($A109="",$C109="",$D109="",$C109>Q$6,$D109<Q$9),"",IF($J109="里程碑","◆","")) | R109: =IF(OR($A109="",$C109="",$D109="",$C109>R$6,$D109<R$9),"",IF($J109="里程碑","◆","")) | ... DB109: =IF(OR($A109="",$C109="",$D109="",$C109>DB$6,$D109<DB$9),"",IF($J109="里程碑","◆","")) | DC109: =IF(ROW()-9>$DH$3,"",MATCH(ROW()-9,排期计算!$U$10:$U$109,0)) | DD109: =IF($DC109="","",INDEX(排期计算!$L$10:$L$109,$DC109))

Sheet 任务编辑
A2: 动力总成支架开发 · 任务编辑 | D2: 说明：点左侧 + / −；新增：右键任务单元格 → 插入表格行
A3: 在目标任务单元格右键：插入 → 表格行（上方）。填黄色格，灰色列自动计算。
A4: 插在父任务下面后，填 WBS 如 2.1.1。位置决定编辑顺序，WBS 决定浏览层级和排序。
A5: 按 WBS 父子关系汇总；空日期一级项作为汇总，填写日期的无下级项按叶子类型计算。
A6: 删除用“操作”列；删父项同时排除下级。支持三级、最多 100 项；前置任务不自动排期。
A7: 说明区默认折叠，点左侧 + 展开。自由插行为免宏模式，操作页不强制锁格，计算页受保护。
A9: WBS | B9: 任务名称 | C9: 负责人 | D9: 输入开始 | E9: 输入结束 | F9: 工期(叶子) | G9: 输入完成度 | H9: 前置任务 WBS | I9: 叶子类型 | J9: 操作 | K9: 实际类型 | L9: 层级 | M9: 生效开始 | N9: 生效结束 | O9: 生效完成度 | P9: 填写检查
A10: 1 | B10: 设计开发 | C10: 张工 | F10: =IF(TimingTasks[[#This Row],[WBS]]="","",INDEX(排期计算!$F$10:$F$109,MATCH("W"&TimingTasks[[#This Row],[WBS]],排期计算!$AG$10:$AG$109,0))) | G10: 0 | I10: 普通任务 | J10: 保留 | K10: =IF(TimingTasks[[#This Row],[WBS]]="","",INDEX(排期计算!$K$10:$K$109,MATCH("W"&TimingTasks[[#This Row],[WBS]],排期计算!$AG$10:$AG$109,0))) -> 汇总 | L10: =IF(TimingTasks[[#This Row],[WBS]]="","",INDEX(排期计算!$L$10:$L$109,MATCH("W"&TimingTasks[[#This Row],[WBS]],排期计算!$AG$10:$AG$109,0))) -> 1 | M10: =IF(TimingTasks[[#This Row],[WBS]]="","",INDEX(排期计算!$M$10:$M$109,MATCH("W"&TimingTasks[[#This Row],[WBS]],排期计算!$AG$10:$AG$109,0))) -> 46321 | N10: =IF(TimingTasks[[#This Row],[WBS]]="","",INDEX(排期计算!$N$10:$N$109,MATCH("W"&TimingTasks[[#This Row],[WBS]],排期计算!$AG$10:$AG$109,0))) -> 46330 | O10: =IF(TimingTasks[[#This Row],[WBS]]="","",INDEX(排期计算!$O$10:$O$109,MATCH("W"&TimingTasks[[#This Row],[WBS]],排期计算!$AG$10:$AG$109,0))) -> 0.41 | P10: =IF(TimingTasks[[#This Row],[WBS]]="","",INDEX(排期计算!$X$10:$X$109,MATCH("W"&TimingTasks[[#This Row],[WBS]],排期计算!$AG$10:$AG$109,0))) -> 由下级汇总
A11: 1.1 | B11: 需求与接口确认 | C11: 张工 | D11: 46321 | E11: 46322 | F11: =IF(TimingTasks[[#This Row],[WBS]]="","",INDEX(排期计算!$F$10:$F$109,MATCH("W"&TimingTasks[[#This Row],[WBS]],排期计算!$AG$10:$AG$109,0))) -> 2 | G11: 1 | I11: 普通任务 | J11: 保留 | K11: =IF(TimingTasks[[#This Row],[WBS]]="","",INDEX(排期计算!$K$10:$K$109,MATCH("W"&TimingTasks[[#This Row],[WBS]],排期计算!$AG$10:$AG$109,0))) -> 普通任务 | L11: =IF(TimingTasks[[#This Row],[WBS]]="","",INDEX(排期计算!$L$10:$L$109,MATCH("W"&TimingTasks[[#This Row],[WBS]],排期计算!$AG$10:$AG$109,0))) -> 2 | M11: =IF(TimingTasks[[#This Row],[WBS]]="","",INDEX(排期计算!$M$10:$M$109,MATCH("W"&TimingTasks[[#This Row],[WBS]],排期计算!$AG$10:$AG$109,0))) -> 46321 | N11: =IF(TimingTasks[[#This Row],[WBS]]="","",INDEX(排期计算!$N$10:$N$109,MATCH("W"&TimingTasks[[#This Row],[WBS]],排期计算!$AG$10:$AG$109,0))) -> 46322 | O11: =IF(TimingTasks[[#This Row],[WBS]]="","",INDEX(排期计算!$O$10:$O$109,MATCH("W"&TimingTasks[[#This Row],[WBS]],排期计算!$AG$10:$AG$109,0))) -> 1 | P11: =IF(TimingTasks[[#This Row],[WBS]]="","",INDEX(排期计算!$X$10:$X$109,MATCH("W"&TimingTasks[[#This Row],[WBS]],排期计算!$AG$10:$AG$109,0)))
A12: 1.2 | B12: 结构方案及设计评审 | C12: 张工 | D12: 46323 | E12: 46329 | F12: =IF(TimingTasks[[#This Row],[WBS]]="","",INDEX(排期计算!$F$10:$F$109,MATCH("W"&TimingTasks[[#This Row],[WBS]],排期计算!$AG$10:$AG$109,0))) -> 5 | G12: 0.25 | H12: 1.1 | I12: 普通任务 | J12: 保留 | K12: =IF(TimingTasks[[#This Row],[WBS]]="","",INDEX(排期计算!$K$10:$K$109,MATCH("W"&TimingTasks[[#This Row],[WBS]],排期计算!$AG$10:$AG$109,0))) -> 普通任务 | L12: =IF(TimingTasks[[#This Row],[WBS]]="","",INDEX(排期计算!$L$10:$L$109,MATCH("W"&TimingTasks[[#This Row],[WBS]],排期计算!$AG$10:$AG$109,0))) -> 2 | M12: =IF(TimingTasks[[#This Row],[WBS]]="","",INDEX(排期计算!$M$10:$M$109,MATCH("W"&TimingTasks[[#This Row],[WBS]],排期计算!$AG$10:$AG$109,0))) -> 46323 | N12: =IF(TimingTasks[[#This Row],[WBS]]="","",INDEX(排期计算!$N$10:$N$109,MATCH("W"&TimingTasks[[#This Row],[WBS]],排期计算!$AG$10:$AG$109,0))) -> 46329 | O12: =IF(TimingTasks[[#This Row],[WBS]]="","",INDEX(排期计算!$O$10:$O$109,MATCH("W"&TimingTasks[[#This Row],[WBS]],排期计算!$AG$10:$AG$109,0))) -> 0.25 | P12: =IF(TimingTasks[[#This Row],[WBS]]="","",INDEX(排期计算!$X$10:$X$109,MATCH("W"&TimingTasks[[#This Row],[WBS]],排期计算!$AG$10:$AG$109,0)))
A13: 1.3 | B13: 客户认可 | C13: 张工 | D13: 46330 | E13: 46330 | F13: =IF(TimingTasks[[#This Row],[WBS]]="","",INDEX(排期计算!$F$10:$F$109,MATCH("W"&TimingTasks[[#This Row],[WBS]],排期计算!$AG$10:$AG$109,0))) -> 0 | G13: 0 | H13: 1.2 | I13: 里程碑 | J13: 保留 | K13: =IF(TimingTasks[[#This Row],[WBS]]="","",INDEX(排期计算!$K$10:$K$109,MATCH("W"&TimingTasks[[#This Row],[WBS]],排期计算!$AG$10:$AG$109,0))) -> 里程碑 | L13: =IF(TimingTasks[[#This Row],[WBS]]="","",INDEX(排期计算!$L$10:$L$109,MATCH("W"&TimingTasks[[#This Row],[WBS]],排期计算!$AG$10:$AG$109,0))) -> 2 | M13: =IF(TimingTasks[[#This Row],[WBS]]="","",INDEX(排期计算!$M$10:$M$109,MATCH("W"&TimingTasks[[#This Row],[WBS]],排期计算!$AG$10:$AG$109,0))) -> 46330 | N13: =IF(TimingTasks[[#This Row],[WBS]]="","",INDEX(排期计算!$N$10:$N$109,MATCH("W"&TimingTasks[[#This Row],[WBS]],排期计算!$AG$10:$AG$109,0))) -> 46330 | O13: =IF(TimingTasks[[#This Row],[WBS]]="","",INDEX(排期计算!$O$10:$O$109,MATCH("W"&TimingTasks[[#This Row],[WBS]],排期计算!$AG$10:$AG$109,0))) -> 0 | P13: =IF(TimingTasks[[#This Row],[WBS]]="","",INDEX(排期计算!$X$10:$X$109,MATCH("W"&TimingTasks[[#This Row],[WBS]],排期计算!$AG$10:$AG$109,0)))
A14: 2 | B14: 试制验证 | C14: 张工 | F14: =IF(TimingTasks[[#This Row],[WBS]]="","",INDEX(排期计算!$F$10:$F$109,MATCH("W"&TimingTasks[[#This Row],[WBS]],排期计算!$AG$10:$AG$109,0))) | G14: 0 | I14: 普通任务 | J14: 保留 | K14: =IF(TimingTasks[[#This Row],[WBS]]="","",INDEX(排期计算!$K$10:$K$109,MATCH("W"&TimingTasks[[#This Row],[WBS]],排期计算!$AG$10:$AG$109,0))) -> 汇总 | L14: =IF(TimingTasks[[#This Row],[WBS]]="","",INDEX(排期计算!$L$10:$L$109,MATCH("W"&TimingTasks[[#This Row],[WBS]],排期计算!$AG$10:$AG$109,0))) -> 1 | M14: =IF(TimingTasks[[#This Row],[WBS]]="","",INDEX(排期计算!$M$10:$M$109,MATCH("W"&TimingTasks[[#This Row],[WBS]],排期计算!$AG$10:$AG$109,0))) -> 46331 | N14: =IF(TimingTasks[[#This Row],[WBS]]="","",INDEX(排期计算!$N$10:$N$109,MATCH("W"&TimingTasks[[#This Row],[WBS]],排期计算!$AG$10:$AG$109,0))) -> 46344 | O14: =IF(TimingTasks[[#This Row],[WBS]]="","",INDEX(排期计算!$O$10:$O$109,MATCH("W"&TimingTasks[[#This Row],[WBS]],排期计算!$AG$10:$AG$109,0))) -> 0 | P14: =IF(TimingTasks[[#This Row],[WBS]]="","",INDEX(排期计算!$X$10:$X$109,MATCH("W"&TimingTasks[[#This Row],[WBS]],排期计算!$AG$10:$AG$109,0))) -> 由下级汇总
A15: 2.1 | B15: 样件制造与试验 | C15: 张工 | D15: 46331 | E15: 46344 | F15: =IF(TimingTasks[[#This Row],[WBS]]="","",INDEX(排期计算!$F$10:$F$109,MATCH("W"&TimingTasks[[#This Row],[WBS]],排期计算!$AG$10:$AG$109,0))) -> 10 | G15: 0 | H15: 1.3 | I15: 普通任务 | J15: 保留 | K15: =IF(TimingTasks[[#This Row],[WBS]]="","",INDEX(排期计算!$K$10:$K$109,MATCH("W"&TimingTasks[[#This Row],[WBS]],排期计算!$AG$10:$AG$109,0))) -> 普通任务 | L15: =IF(TimingTasks[[#This Row],[WBS]]="","",INDEX(排期计算!$L$10:$L$109,MATCH("W"&TimingTasks[[#This Row],[WBS]],排期计算!$AG$10:$AG$109,0))) -> 2 | M15: =IF(TimingTasks[[#This Row],[WBS]]="","",INDEX(排期计算!$M$10:$M$109,MATCH("W"&TimingTasks[[#This Row],[WBS]],排期计算!$AG$10:$AG$109,0))) -> 46331 | N15: =IF(TimingTasks[[#This Row],[WBS]]="","",INDEX(排期计算!$N$10:$N$109,MATCH("W"&TimingTasks[[#This Row],[WBS]],排期计算!$AG$10:$AG$109,0))) -> 46344 | O15: =IF(TimingTasks[[#This Row],[WBS]]="","",INDEX(排期计算!$O$10:$O$109,MATCH("W"&TimingTasks[[#This Row],[WBS]],排期计算!$AG$10:$AG$109,0))) -> 0 | P15: =IF(TimingTasks[[#This Row],[WBS]]="","",INDEX(排期计算!$X$10:$X$109,MATCH("W"&TimingTasks[[#This Row],[WBS]],排期计算!$AG$10:$AG$109,0)))
A16: 3 | B16: 量产移交 | C16: 张工 | D16: 46345 | E16: 46345 | F16: =IF(TimingTasks[[#This Row],[WBS]]="","",INDEX(排期计算!$F$10:$F$109,MATCH("W"&TimingTasks[[#This Row],[WBS]],排期计算!$AG$10:$AG$109,0))) -> 0 | G16: 0 | H16: 2.1 | I16: 里程碑 | J16: 保留 | K16: =IF(TimingTasks[[#This Row],[WBS]]="","",INDEX(排期计算!$K$10:$K$109,MATCH("W"&TimingTasks[[#This Row],[WBS]],排期计算!$AG$10:$AG$109,0))) -> 里程碑 | L16: =IF(TimingTasks[[#This Row],[WBS]]="","",INDEX(排期计算!$L$10:$L$109,MATCH("W"&TimingTasks[[#This Row],[WBS]],排期计算!$AG$10:$AG$109,0))) -> 1 | M16: =IF(TimingTasks[[#This Row],[WBS]]="","",INDEX(排期计算!$M$10:$M$109,MATCH("W"&TimingTasks[[#This Row],[WBS]],排期计算!$AG$10:$AG$109,0))) -> 46345 | N16: =IF(TimingTasks[[#This Row],[WBS]]="","",INDEX(排期计算!$N$10:$N$109,MATCH("W"&TimingTasks[[#This Row],[WBS]],排期计算!$AG$10:$AG$109,0))) -> 46345 | O16: =IF(TimingTasks[[#This Row],[WBS]]="","",INDEX(排期计算!$O$10:$O$109,MATCH("W"&TimingTasks[[#This Row],[WBS]],排期计算!$AG$10:$AG$109,0))) -> 0 | P16: =IF(TimingTasks[[#This Row],[WBS]]="","",INDEX(排期计算!$X$10:$X$109,MATCH("W"&TimingTasks[[#This Row],[WBS]],排期计算!$AG$10:$AG$109,0)))
F17: =IF(TimingTasks[[#This Row],[WBS]]="","",INDEX(排期计算!$F$10:$F$109,MATCH("W"&TimingTasks[[#This Row],[WBS]],排期计算!$AG$10:$AG$109,0))) | K17: =IF(TimingTasks[[#This Row],[WBS]]="","",INDEX(排期计算!$K$10:$K$109,MATCH("W"&TimingTasks[[#This Row],[WBS]],排期计算!$AG$10:$AG$109,0))) | L17: =IF(TimingTasks[[#This Row],[WBS]]="","",INDEX(排期计算!$L$10:$L$109,MATCH("W"&TimingTasks[[#This Row],[WBS]],排期计算!$AG$10:$AG$109,0))) | M17: =IF(TimingTasks[[#This Row],[WBS]]="","",INDEX(排期计算!$M$10:$M$109,MATCH("W"&TimingTasks[[#This Row],[WBS]],排期计算!$AG$10:$AG$109,0))) | N17: =IF(TimingTasks[[#This Row],[WBS]]="","",INDEX(排期计算!$N$10:$N$109,MATCH("W"&TimingTasks[[#This Row],[WBS]],排期计算!$AG$10:$AG$109,0))) | O17: =IF(TimingTasks[[#This Row],[WBS]]="","",INDEX(排期计算!$O$10:$O$109,MATCH("W"&TimingTasks[[#This Row],[WBS]],排期计算!$AG$10:$AG$109,0))) | P17: =IF(TimingTasks[[#This Row],[WBS]]="","",INDEX(排期计算!$X$10:$X$109,MATCH("W"&TimingTasks[[#This Row],[WBS]],排期计算!$AG$10:$AG$109,0)))
F18: =IF(TimingTasks[[#This Row],[WBS]]="","",INDEX(排期计算!$F$10:$F$109,MATCH("W"&TimingTasks[[#This Row],[WBS]],排期计算!$AG$10:$AG$109,0))) | K18: =IF(TimingTasks[[#This Row],[WBS]]="","",INDEX(排期计算!$K$10:$K$109,MATCH("W"&TimingTasks[[#This Row],[WBS]],排期计算!$AG$10:$AG$109,0))) | L18: =IF(TimingTasks[[#This Row],[WBS]]="","",INDEX(排期计算!$L$10:$L$109,MATCH("W"&TimingTasks[[#This Row],[WBS]],排期计算!$AG$10:$AG$109,0))) | M18: =IF(TimingTasks[[#This Row],[WBS]]="","",INDEX(排期计算!$M$10:$M$109,MATCH("W"&TimingTasks[[#This Row],[WBS]],排期计算!$AG$10:$AG$109,0))) | N18: =IF(TimingTasks[[#This Row],[WBS]]="","",INDEX(排期计算!$N$10:$N$109,MATCH("W"&TimingTasks[[#This Row],[WBS]],排期计算!$AG$10:$AG$109,0))) | O18: =IF(TimingTasks[[#This Row],[WBS]]="","",INDEX(排期计算!$O$10:$O$109,MATCH("W"&TimingTasks[[#This Row],[WBS]],排期计算!$AG$10:$AG$109,0))) | P18: =IF(TimingTasks[[#This Row],[WBS]]="","",INDEX(排期计算!$X$10:$X$109,MATCH("W"&TimingTasks[[#This Row],[WBS]],排期计算!$AG$10:$AG$109,0)))
F19: =IF(TimingTasks[[#This Row],[WBS]]="","",INDEX(排期计算!$F$10:$F$109,MATCH("W"&TimingTasks[[#This Row],[WBS]],排期计算!$AG$10:$AG$109,0))) | K19: =IF(TimingTasks[[#This Row],[WBS]]="","",INDEX(排期计算!$K$10:$K$109,MATCH("W"&TimingTasks[[#This Row],[WBS]],排期计算!$AG$10:$AG$109,0))) | L19: =IF(TimingTasks[[#This Row],[WBS]]="","",INDEX(排期计算!$L$10:$L$109,MATCH("W"&TimingTasks[[#This Row],[WBS]],排期计算!$AG$10:$AG$109,0))) | M19: =IF(TimingTasks[[#This Row],[WBS]]="","",INDEX(排期计算!$M$10:$M$109,MATCH("W"&TimingTasks[[#This Row],[WBS]],排期计算!$AG$10:$AG$109,0))) | N19: =IF(TimingTasks[[#This Row],[WBS]]="","",INDEX(排期计算!$N$10:$N$109,MATCH("W"&TimingTasks[[#This Row],[WBS]],排期计算!$AG$10:$AG$109,0))) | O19: =IF(TimingTasks[[#This Row],[WBS]]="","",INDEX(排期计算!$O$10:$O$109,MATCH("W"&TimingTasks[[#This Row],[WBS]],排期计算!$AG$10:$AG$109,0))) | P19: =IF(TimingTasks[[#This Row],[WBS]]="","",INDEX(排期计算!$X$10:$X$109,MATCH("W"&TimingTasks[[#This Row],[WBS]],排期计算!$AG$10:$AG$109,0)))
F20: =IF(TimingTasks[[#This Row],[WBS]]="","",INDEX(排期计算!$F$10:$F$109,MATCH("W"&TimingTasks[[#This Row],[WBS]],排期计算!$AG$10:$AG$109,0))) | K20: =IF(TimingTasks[[#This Row],[WBS]]="","",INDEX(排期计算!$K$10:$K$109,MATCH("W"&TimingTasks[[#This Row],[WBS]],排期计算!$AG$10:$AG$109,0))) | L20: =IF(TimingTasks[[#This Row],[WBS]]="","",INDEX(排期计算!$L$10:$L$109,MATCH("W"&TimingTasks[[#This Row],[WBS]],排期计算!$AG$10:$AG$109,0))) | M20: =IF(TimingTasks[[#This Row],[WBS]]="","",INDEX(排期计算!$M$10:$M$109,MATCH("W"&TimingTasks[[#This Row],[WBS]],排期计算!$AG$10:$AG$109,0))) | N20: =IF(TimingTasks[[#This Row],[WBS]]="","",INDEX(排期计算!$N$10:$N$109,MATCH("W"&TimingTasks[[#This Row],[WBS]],排期计算!$AG$10:$AG$109,0))) | O20: =IF(TimingTasks[[#This Row],[WBS]]="","",INDEX(排期计算!$O$10:$O$109,MATCH("W"&TimingTasks[[#This Row],[WBS]],排期计算!$AG$10:$AG$109,0))) | P20: =IF(TimingTasks[[#This Row],[WBS]]="","",INDEX(排期计算!$X$10:$X$109,MATCH("W"&TimingTasks[[#This Row],[WBS]],排期计算!$AG$10:$AG$109,0)))
F21: =IF(TimingTasks[[#This Row],[WBS]]="","",INDEX(排期计算!$F$10:$F$109,MATCH("W"&TimingTasks[[#This Row],[WBS]],排期计算!$AG$10:$AG$109,0))) | K21: =IF(TimingTasks[[#This Row],[WBS]]="","",INDEX(排期计算!$K$10:$K$109,MATCH("W"&TimingTasks[[#This Row],[WBS]],排期计算!$AG$10:$AG$109,0))) | L21: =IF(TimingTasks[[#This Row],[WBS]]="","",INDEX(排期计算!$L$10:$L$109,MATCH("W"&TimingTasks[[#This Row],[WBS]],排期计算!$AG$10:$AG$109,0))) | M21: =IF(TimingTasks[[#This Row],[WBS]]="","",INDEX(排期计算!$M$10:$M$109,MATCH("W"&TimingTasks[[#This Row],[WBS]],排期计算!$AG$10:$AG$109,0))) | N21: =IF(TimingTasks[[#This Row],[WBS]]="","",INDEX(排期计算!$N$10:$N$109,MATCH("W"&TimingTasks[[#This Row],[WBS]],排期计算!$AG$10:$AG$109,0))) | O21: =IF(TimingTasks[[#This Row],[WBS]]="","",INDEX(排期计算!$O$10:$O$109,MATCH("W"&TimingTasks[[#This Row],[WBS]],排期计算!$AG$10:$AG$109,0))) | P21: =IF(TimingTasks[[#This Row],[WBS]]="","",INDEX(排期计算!$X$10:$X$109,MATCH("W"&TimingTasks[[#This Row],[WBS]],排期计算!$AG$10:$AG$109,0)))
F22: =IF(TimingTasks[[#This Row],[WBS]]="","",INDEX(排期计算!$F$10:$F$109,MATCH("W"&TimingTasks[[#This Row],[WBS]],排期计算!$AG$10:$AG$109,0))) | K22: =IF(TimingTasks[[#This Row],[WBS]]="","",INDEX(排期计算!$K$10:$K$109,MATCH("W"&TimingTasks[[#This Row],[WBS]],排期计算!$AG$10:$AG$109,0))) | L22: =IF(TimingTasks[[#This Row],[WBS]]="","",INDEX(排期计算!$L$10:$L$109,MATCH("W"&TimingTasks[[#This Row],[WBS]],排期计算!$AG$10:$AG$109,0))) | M22: =IF(TimingTasks[[#This Row],[WBS]]="","",INDEX(排期计算!$M$10:$M$109,MATCH("W"&TimingTasks[[#This Row],[WBS]],排期计算!$AG$10:$AG$109,0))) | N22: =IF(TimingTasks[[#This Row],[WBS]]="","",INDEX(排期计算!$N$10:$N$109,MATCH("W"&TimingTasks[[#This Row],[WBS]],排期计算!$AG$10:$AG$109,0))) | O22: =IF(TimingTasks[[#This Row],[WBS]]="","",INDEX(排期计算!$O$10:$O$109,MATCH("W"&TimingTasks[[#This Row],[WBS]],排期计算!$AG$10:$AG$109,0))) | P22: =IF(TimingTasks[[#This Row],[WBS]]="","",INDEX(排期计算!$X$10:$X$109,MATCH("W"&TimingTasks[[#This Row],[WBS]],排期计算!$AG$10:$AG$109,0)))
F23: =IF(TimingTasks[[#This Row],[WBS]]="","",INDEX(排期计算!$F$10:$F$109,MATCH("W"&TimingTasks[[#This Row],[WBS]],排期计算!$AG$10:$AG$109,0))) | K23: =IF(TimingTasks[[#This Row],[WBS]]="","",INDEX(排期计算!$K$10:$K$109,MATCH("W"&TimingTasks[[#This Row],[WBS]],排期计算!$AG$10:$AG$109,0))) | L23: =IF(TimingTasks[[#This Row],[WBS]]="","",INDEX(排期计算!$L$10:$L$109,MATCH("W"&TimingTasks[[#This Row],[WBS]],排期计算!$AG$10:$AG$109,0))) | M23: =IF(TimingTasks[[#This Row],[WBS]]="","",INDEX(排期计算!$M$10:$M$109,MATCH("W"&TimingTasks[[#This Row],[WBS]],排期计算!$AG$10:$AG$109,0))) | N23: =IF(TimingTasks[[#This Row],[WBS]]="","",INDEX(排期计算!$N$10:$N$109,MATCH("W"&TimingTasks[[#This Row],[WBS]],排期计算!$AG$10:$AG$109,0))) | O23: =IF(TimingTasks[[#This Row],[WBS]]="","",INDEX(排期计算!$O$10:$O$109,MATCH("W"&TimingTasks[[#This Row],[WBS]],排期计算!$AG$10:$AG$109,0))) | P23: =IF(TimingTasks[[#This Row],[WBS]]="","",INDEX(排期计算!$X$10:$X$109,MATCH("W"&TimingTasks[[#This Row],[WBS]],排期计算!$AG$10:$AG$109,0)))
F24: =IF(TimingTasks[[#This Row],[WBS]]="","",INDEX(排期计算!$F$10:$F$109,MATCH("W"&TimingTasks[[#This Row],[WBS]],排期计算!$AG$10:$AG$109,0))) | K24: =IF(TimingTasks[[#This Row],[WBS]]="","",INDEX(排期计算!$K$10:$K$109,MATCH("W"&TimingTasks[[#This Row],[WBS]],排期计算!$AG$10:$AG$109,0))) | L24: =IF(TimingTasks[[#This Row],[WBS]]="","",INDEX(排期计算!$L$10:$L$109,MATCH("W"&TimingTasks[[#This Row],[WBS]],排期计算!$AG$10:$AG$109,0))) | M24: =IF(TimingTasks[[#This Row],[WBS]]="","",INDEX(排期计算!$M$10:$M$109,MATCH("W"&TimingTasks[[#This Row],[WBS]],排期计算!$AG$10:$AG$109,0))) | N24: =IF(TimingTasks[[#This Row],[WBS]]="","",INDEX(排期计算!$N$10:$N$109,MATCH("W"&TimingTasks[[#This Row],[WBS]],排期计算!$AG$10:$AG$109,0))) | O24: =IF(TimingTasks[[#This Row],[WBS]]="","",INDEX(排期计算!$O$10:$O$109,MATCH("W"&TimingTasks[[#This Row],[WBS]],排期计算!$AG$10:$AG$109,0))) | P24: =IF(TimingTasks[[#This Row],[WBS]]="","",INDEX(排期计算!$X$10:$X$109,MATCH("W"&TimingTasks[[#This Row],[WBS]],排期计算!$AG$10:$AG$109,0)))
F25: =IF(TimingTasks[[#This Row],[WBS]]="","",INDEX(排期计算!$F$10:$F$109,MATCH("W"&TimingTasks[[#This Row],[WBS]],排期计算!$AG$10:$AG$109,0))) | K25: =IF(TimingTasks[[#This Row],[WBS]]="","",INDEX(排期计算!$K$10:$K$109,MATCH("W"&TimingTasks[[#This Row],[WBS]],排期计算!$AG$10:$AG$109,0))) | L25: =IF(TimingTasks[[#This Row],[WBS]]="","",INDEX(排期计算!$L$10:$L$109,MATCH("W"&TimingTasks[[#This Row],[WBS]],排期计算!$AG$10:$AG$109,0))) | M25: =IF(TimingTasks[[#This Row],[WBS]]="","",INDEX(排期计算!$M$10:$M$109,MATCH("W"&TimingTasks[[#This Row],[WBS]],排期计算!$AG$10:$AG$109,0))) | N25: =IF(TimingTasks[[#This Row],[WBS]]="","",INDEX(排期计算!$N$10:$N$109,MATCH("W"&TimingTasks[[#This Row],[WBS]],排期计算!$AG$10:$AG$109,0))) | O25: =IF(TimingTasks[[#This Row],[WBS]]="","",INDEX(排期计算!$O$10:$O$109,MATCH("W"&TimingTasks[[#This Row],[WBS]],排期计算!$AG$10:$AG$109,0))) | P25: =IF(TimingTasks[[#This Row],[WBS]]="","",INDEX(排期计算!$X$10:$X$109,MATCH("W"&TimingTasks[[#This Row],[WBS]],排期计算!$AG$10:$AG$109,0)))
F26: =IF(TimingTasks[[#This Row],[WBS]]="","",INDEX(排期计算!$F$10:$F$109,MATCH("W"&TimingTasks[[#This Row],[WBS]],排期计算!$AG$10:$AG$109,0))) | K26: =IF(TimingTasks[[#This Row],[WBS]]="","",INDEX(排期计算!$K$10:$K$109,MATCH("W"&TimingTasks[[#This Row],[WBS]],排期计算!$AG$10:$AG$109,0))) | L26: =IF(TimingTasks[[#This Row],[WBS]]="","",INDEX(排期计算!$L$10:$L$109,MATCH("W"&TimingTasks[[#This Row],[WBS]],排期计算!$AG$10:$AG$109,0))) | M26: =IF(TimingTasks[[#This Row],[WBS]]="","",INDEX(排期计算!$M$10:$M$109,MATCH("W"&TimingTasks[[#This Row],[WBS]],排期计算!$AG$10:$AG$109,0))) | N26: =IF(TimingTasks[[#This Row],[WBS]]="","",INDEX(排期计算!$N$10:$N$109,MATCH("W"&TimingTasks[[#This Row],[WBS]],排期计算!$AG$10:$AG$109,0))) | O26: =IF(TimingTasks[[#This Row],[WBS]]="","",INDEX(排期计算!$O$10:$O$109,MATCH("W"&TimingTasks[[#This Row],[WBS]],排期计算!$AG$10:$AG$109,0))) | P26: =IF(TimingTasks[[#This Row],[WBS]]="","",INDEX(排期计算!$X$10:$X$109,MATCH("W"&TimingTasks[[#This Row],[WBS]],排期计算!$AG$10:$AG$109,0)))
F27: =IF(TimingTasks[[#This Row],[WBS]]="","",INDEX(排期计算!$F$10:$F$109,MATCH("W"&TimingTasks[[#This Row],[WBS]],排期计算!$AG$10:$AG$109,0))) | K27: =IF(TimingTasks[[#This Row],[WBS]]="","",INDEX(排期计算!$K$10:$K$109,MATCH("W"&TimingTasks[[#This Row],[WBS]],排期计算!$AG$10:$AG$109,0))) | L27: =IF(TimingTasks[[#This Row],[WBS]]="","",INDEX(排期计算!$L$10:$L$109,MATCH("W"&TimingTasks[[#This Row],[WBS]],排期计算!$AG$10:$AG$109,0))) | M27: =IF(TimingTasks[[#This Row],[WBS]]="","",INDEX(排期计算!$M$10:$M$109,MATCH("W"&TimingTasks[[#This Row],[WBS]],排期计算!$AG$10:$AG$109,0))) | N27: =IF(TimingTasks[[#This Row],[WBS]]="","",INDEX(排期计算!$N$10:$N$109,MATCH("W"&TimingTasks[[#This Row],[WBS]],排期计算!$AG$10:$AG$109,0))) | O27: =IF(TimingTasks[[#This Row],[WBS]]="","",INDEX(排期计算!$O$10:$O$109,MATCH("W"&TimingTasks[[#This Row],[WBS]],排期计算!$AG$10:$AG$109,0))) | P27: =IF(TimingTasks[[#This Row],[WBS]]="","",INDEX(排期计算!$X$10:$X$109,MATCH("W"&TimingTasks[[#This Row],[WBS]],排期计算!$AG$10:$AG$109,0)))
F28: =IF(TimingTasks[[#This Row],[WBS]]="","",INDEX(排期计算!$F$10:$F$109,MATCH("W"&TimingTasks[[#This Row],[WBS]],排期计算!$AG$10:$AG$109,0))) | K28: =IF(TimingTasks[[#This Row],[WBS]]="","",INDEX(排期计算!$K$10:$K$109,MATCH("W"&TimingTasks[[#This Row],[WBS]],排期计算!$AG$10:$AG$109,0))) | L28: =IF(TimingTasks[[#This Row],[WBS]]="","",INDEX(排期计算!$L$10:$L$109,MATCH("W"&TimingTasks[[#This Row],[WBS]],排期计算!$AG$10:$AG$109,0))) | M28: =IF(TimingTasks[[#This Row],[WBS]]="","",INDEX(排期计算!$M$10:$M$109,MATCH("W"&TimingTasks[[#This Row],[WBS]],排期计算!$AG$10:$AG$109,0))) | N28: =IF(TimingTasks[[#This Row],[WBS]]="","",INDEX(排期计算!$N$10:$N$109,MATCH("W"&TimingTasks[[#This Row],[WBS]],排期计算!$AG$10:$AG$109,0))) | O28: =IF(TimingTasks[[#This Row],[WBS]]="","",INDEX(排期计算!$O$10:$O$109,MATCH("W"&TimingTasks[[#This Row],[WBS]],排期计算!$AG$10:$AG$109,0))) | P28: =IF(TimingTasks[[#This Row],[WBS]]="","",INDEX(排期计算!$X$10:$X$109,MATCH("W"&TimingTasks[[#This Row],[WBS]],排期计算!$AG$10:$AG$109,0)))
F29: =IF(TimingTasks[[#This Row],[WBS]]="","",INDEX(排期计算!$F$10:$F$109,MATCH("W"&TimingTasks[[#This Row],[WBS]],排期计算!$AG$10:$AG$109,0))) | K29: =IF(TimingTasks[[#This Row],[WBS]]="","",INDEX(排期计算!$K$10:$K$109,MATCH("W"&TimingTasks[[#This Row],[WBS]],排期计算!$AG$10:$AG$109,0))) | L29: =IF(TimingTasks[[#This Row],[WBS]]="","",INDEX(排期计算!$L$10:$L$109,MATCH("W"&TimingTasks[[#This Row],[WBS]],排期计算!$AG$10:$AG$109,0))) | M29: =IF(TimingTasks[[#This Row],[WBS]]="","",INDEX(排期计算!$M$10:$M$109,MATCH("W"&TimingTasks[[#This Row],[WBS]],排期计算!$AG$10:$AG$109,0))) | N29: =IF(TimingTasks[[#This Row],[WBS]]="","",INDEX(排期计算!$N$10:$N$109,MATCH("W"&TimingTasks[[#This Row],[WBS]],排期计算!$AG$10:$AG$109,0))) | O29: =IF(TimingTasks[[#This Row],[WBS]]="","",INDEX(排期计算!$O$10:$O$109,MATCH("W"&TimingTasks[[#This Row],[WBS]],排期计算!$AG$10:$AG$109,0))) | P29: =IF(TimingTasks[[#This Row],[WBS]]="","",INDEX(排期计算!$X$10:$X$109,MATCH("W"&TimingTasks[[#This Row],[WBS]],排期计算!$AG$10:$AG$109,0)))

Sheet 排期计算
A9: WBS | B9: 任务名称 | C9: 负责人 | D9: 输入开始 | E9: 输入结束 | F9: 工期(叶子) | G9: 输入完成度 | H9: 前置任务 WBS | I9: 叶子类型 | J9: 操作 | K9: 实际类型 | L9: 层级 | M9: 生效开始 | N9: 生效结束 | O9: 生效完成度 | P9: 参与计算 | Q9: 叶子权重 | R9: 加权完成 | S9: 排序编码 | T9: 显示标记 | U9: 显示序号 | V9: 父 WBS | W9: 顶层 WBS | X9: 填写检查 | Y9: 叶子开始 | Z9: 叶子结束 | AA9: 叶子标记 | AB9: 一级段 | AC9: 二级段 | AD9: 三级段 | AE9: 编号有效 | AF9: 样品 ID
